Workbook
Name POD_Paper_Codes: '07-Paper Priority'!$B$5:$B$26

Sheet 00-README
A1: POD Printing Size Strategy - Whole-mm Output
A2: A/B paper-size codes are used directly as DTF garment-transfer print sizes; there is no separate DTF code block. All working dimensions, including LCCO2, round down to whole millimetres.
A4: What changed
A5: Negative sizes removed | B5: The fixed 20 mm deduction pattern was replaced by proportional fractions, fitted aspect ratios and minimum-size checks.
A6: Process strategy | B6: UV and LCCO2 use fixed-bed validation; SINK uses roll-width validation; A/B paper envelopes are the DTF transfer-size codes.
A7: Codes preserved | B7: A/B, UV, LCCO2, SINK and CT remain. The separate DTF size block has been removed because A/B codes are used for garment transfers.
A8: The last 15 codes in every A/B and machine-process block remain manual custom slots. All custom entries must be positive whole millimetres. | B8: The last 15 codes in every A/B and machine-process block remain manual custom slots. All custom entries must be whole millimetres.
A9: Original retained | B9: The original worksheet values are retained in 99-Original Backup for comparison.
A11: Code | B11: Meaning | C11: Sizing rule | D11: Width / height meaning | E11: Production caution | F11: Primary source / basis
A12: A0-A12 / B0-B10 | B12: ISO-style paper envelopes used directly for DTF garment-transfer sizes | C12: 56 adaptive generated candidates + 15 custom slots; generated sizes round down to whole mm | D12: Physical paper/transfer bounding box; rotation allowed when the product permits | E12: A11/A12 are geometric continuation codes for compatibility, not claimed as ISO 216 standard sizes | F12: https://www.iso.org/standard/36631.html
A13: DTF sizing (no separate code block) | B13: Select the A/B printing_size code itself | C13: Example: A3 Full remains exactly 297 x 420 mm | D13: The A/B dimensions are the transfer-print dimensions used on the garment | E13: Verify that the selected transfer fits the actual garment and heat-press area | F13: https://www.iso.org/standard/36631.html
A14: UV | B14: UV flatbed printing | C14: Nominal bed, safe bed and common product starting presets | D14: Fixed bed; either orientation may fit | E14: Jigs, vacuum zones, rotary attachments and object height reduce usable area | F14: https://mimaki.com/product/inkjet/i-flat/ujf-6042mkII-e/specification.html
A15: LCCO2 | B15: CO2 laser cutting/engraving | C15: Nominal bed, safe bed, stock and product bounding boxes | D15: Fixed bed; either orientation may fit | E15: Kerf, material, clamps and extraction clearance are not represented by width/height alone | F15: https://www.troteclaser.com/en-tt/laser-machines/affordable-laser-cutter-r-series
A16: SINK | B16: Solvent-ink banner/sign printing | C16: Common banner panels plus custom slots | D16: width_mm = across roll; height_mm = feed length | E16: Roll length is variable; finishing, hems and eyelets need separate allowances | F16: https://downloadcenter.rolanddg.com/contents/manuals/VG3-640_INS_EN/gxd1623374300487.html
A17: CT | B17: Custom sizes | C17: Manual entries preserved from the original workbook | D17: User-defined | E17: Enter both dimensions and verify against the chosen process | F17: User-provided values
A19: Operating rules
A20: 1. For DTF garment prints, select an A/B code directly. Example: A3 Full = 297 x 420 mm.
A21: 2. Every calculated size, including LCCO2, is rounded down to a whole millimetre after the size formula is applied.
A22: 3. All custom-entry cells accept positive whole-millimetre values only. Keep kerf and other sub-millimetre production adjustments in the design or machine file.
A23: 4. For fixed-bed UV/LCCO2, a size is valid when it fits in either orientation. Nominal edge means it fits the stated bed but not the configured margin.
A24: 5. For SINK, width_mm is the cross-roll dimension and height_mm is the feed direction. Hems, eyelets and bleed remain separate.
A25: 6. Filter validation_status in 02-Printing Size before exporting. Do not import ERROR rows.
A26: 7. In 03-POD Product Guide, apparel positions use a minimum starting paper and select the first full A/B code that fits. For bodysuits the search begins A5 -> B5 -> A4; the selected base code is the full transfer size.
A27: Why exact product print areas cannot be universal
A28: POD platforms and blank suppliers publish print areas per individual product, placement and sometimes garment size. Use this workbook to control safe, non-negative dimensions, then verify the final template for each SKU.
A29: Product-specific dimensions guidance | B29: https://help.printify.com/hc/en-us/articles/4483601892497-What-dimensions-should-my-design-be
A30: Safe print area guidance | B30: https://help.printful.com/hc/en-us/articles/10720620016540-What-is-the-safe-print-area

Sheet 01-Process Controls
A1: Process Controls
A2: Blue/yellow cells are production inputs. A/B paper codes are the DTF transfer sizes. Use whole millimetres for ISO/DTF, UV, LCCO2, SINK and CT.
A4: process_code | B4: process_name | C4: feed_type | D4: max_width_mm | E4: max_height_mm | F4: default_work_length_mm | G4: min_practical_dimension_mm | H4: safe_edge_margin_each_side_mm | I4: rotation_allowed | J4: confirmed_against_machine | K4: basis / action | L4: source_url_1 | M4: source_url_2
A5: ISO | B5: A/B paper sizes used for DTF transfers | C5: SHEET / TRANSFER | G5: 3 | H5: 0 | I5: Yes | J5: Yes | K5: Use A/B printing_size codes directly for garment transfers; e.g. A3 Full = 297 x 420 mm. Generated candidates round down to whole millimetres. A11/A12 remain compatibility extensions. | L5: https://www.iso.org/standard/36631.html
A7: UV | B7: UV flatbed printing | C7: FLATBED | D7: 600 | E7: 900 | F7: 900 | G7: 5 | H7: 10 | I7: Yes | J7: No | K7: Nominal 600 x 900 mm copied from the original workbook. Confirm printable area, jig and object-height limits. Production dimensions round down to whole millimetres. | L7: https://mimaki.com/product/inkjet/i-flat/ujf-6042mkII-e/specification.html
A8: LCCO2 | B8: CO2 laser cut / engrave | C8: FLATBED | D8: 1300 | E8: 900 | F8: 900 | G8: 5 | H8: 10 | I8: Yes | J8: No | K8: Nominal 1300 x 900 mm copied from the original workbook. LCCO2 size codes round down to whole millimetres; keep kerf and precise vector geometry in the laser/CAD file. | L8: https://www.troteclaser.com/en-tt/laser-machines/affordable-laser-cutter-r-series
A9: SINK | B9: Solvent ink banner / sign | C9: ROLL | D9: 1600 | F9: 1000 | G9: 100 | H9: 10 | I9: No | J9: No | K9: 1600 mm is treated as cross-roll printable width. Feed length is variable; 1000 mm is only the default panel. Production dimensions round down to whole millimetres. | L9: https://downloadcenter.rolanddg.com/contents/manuals/VG3-640_INS_EN/gxd1623374300487.html
A10: CT | B10: Custom manual sizes | C10: CUSTOM | G10: 1 | H10: 0 | I10: Yes | J10: N/A | K10: No fixed envelope. Custom sizes are whole millimetres and must be checked against the actual process. Keep any sub-millimetre kerf or tool-path adjustment in the production file.

Sheet 02-Printing Size
A1: printing_size | B1: width_mm | C1: height_mm | D1: process_code | E1: category | F1: preset_rule | G1: common_use | H1: validation_status | I1: production_note | J1: base_width_mm | K1: base_height_mm | L1: min_dimension_mm | M1: candidate_width_mm | N1: candidate_height_mm | O1: rule_id | P1: cm | Q1: cm | R1: inche | S1: inches | T1: feet | U1: feet | V1: m | W1: m
A2: A0 | B2: =IF(LEFT(H2,5)="VALID",M2,"") -> 841 | C2: =IF(LEFT(H2,5)="VALID",N2,"") -> 1189 | D2: ISO | E2: A0 paper / DTF variant | F2: Full paper size | G2: Use the complete paper/transfer width and height. | H2: ="VALID - BASE" -> VALID - BASE | I2: Generated inside the A0 paper/DTF envelope. Generated dimensions round down to whole millimetres; below-minimum or duplicate candidates are skipped. | J2: ='05-ISO Reference'!$B$5 -> 841 | K2: ='05-ISO Reference'!$C$5 -> 1189 | L2: ='01-Process Controls'!$G$5 -> 3 | M2: =ROUNDDOWN(J2,0) -> 841 | N2: =ROUNDDOWN(K2,0) -> 1189 | O2: 0
A3: A0-1 | B3: =IF(LEFT(H3,5)="VALID",M3,"") -> 420 | C3: =IF(LEFT(H3,5)="VALID",N3,"") -> 1189 | D3: ISO | E3: A0 paper / DTF variant | F3: Half width | G3: Half the width; full height. | H3: =IF(OR(M3<=0,N3<=0),"SKIPPED - NONPOSITIVE",IF(OR(M3<L3,N3<L3),"SKIPPED - BELOW MIN",IF(OR(M3>J3,N3>K3),"SKIPPED - EXCEEDS BASE",IF(COUNTIFS($M$2:M2,M3,$N$2:N2,N3)>0,"SKIPPED - DUPLICATE","VALID - GENERATED")))) -> VALID - GENERATED | I3: Generated inside the A0 paper/DTF envelope. Generated dimensions round down to whole millimetres; below-minimum or duplicate candidates are skipped. | J3: ='05-ISO Reference'!$B$5 -> 841 | K3: ='05-ISO Reference'!$C$5 -> 1189 | L3: ='01-Process Controls'!$G$5 -> 3 | M3: =ROUNDDOWN(J3*'04-Variant Rules'!$D$6,0) -> 420 | N3: =ROUNDDOWN(K3,0) -> 1189 | O3: 1
A4: A0-2 | B4: =IF(LEFT(H4,5)="VALID",M4,"") -> 280 | C4: =IF(LEFT(H4,5)="VALID",N4,"") -> 1189 | D4: ISO | E4: A0 paper / DTF variant | F4: Third width | G4: One-third width; full height. | H4: =IF(OR(M4<=0,N4<=0),"SKIPPED - NONPOSITIVE",IF(OR(M4<L4,N4<L4),"SKIPPED - BELOW MIN",IF(OR(M4>J4,N4>K4),"SKIPPED - EXCEEDS BASE",IF(COUNTIFS($M$2:M3,M4,$N$2:N3,N4)>0,"SKIPPED - DUPLICATE","VALID - GENERATED")))) -> VALID - GENERATED | I4: Generated inside the A0 paper/DTF envelope. Generated dimensions round down to whole millimetres; below-minimum or duplicate candidates are skipped. | J4: ='05-ISO Reference'!$B$5 -> 841 | K4: ='05-ISO Reference'!$C$5 -> 1189 | L4: ='01-Process Controls'!$G$5 -> 3 | M4: =ROUNDDOWN(J4*'04-Variant Rules'!$D$7,0) -> 280 | N4: =ROUNDDOWN(K4,0) -> 1189 | O4: 2
A5: A0-3 | B5: =IF(LEFT(H5,5)="VALID",M5,"") -> 210 | C5: =IF(LEFT(H5,5)="VALID",N5,"") -> 1189 | D5: ISO | E5: A0 paper / DTF variant | F5: Quarter width | G5: Quarter width; full height. | H5: =IF(OR(M5<=0,N5<=0),"SKIPPED - NONPOSITIVE",IF(OR(M5<L5,N5<L5),"SKIPPED - BELOW MIN",IF(OR(M5>J5,N5>K5),"SKIPPED - EXCEEDS BASE",IF(COUNTIFS($M$2:M4,M5,$N$2:N4,N5)>0,"SKIPPED - DUPLICATE","VALID - GENERATED")))) -> VALID - GENERATED | I5: Generated inside the A0 paper/DTF envelope. Generated dimensions round down to whole millimetres; below-minimum or duplicate candidates are skipped. | J5: ='05-ISO Reference'!$B$5 -> 841 | K5: ='05-ISO Reference'!$C$5 -> 1189 | L5: ='01-Process Controls'!$G$5 -> 3 | M5: =ROUNDDOWN(J5*'04-Variant Rules'!$D$8,0) -> 210 | N5: =ROUNDDOWN(K5,0) -> 1189 | O5: 3
A6: A0-4 | B6: =IF(LEFT(H6,5)="VALID",M6,"") -> 560 | C6: =IF(LEFT(H6,5)="VALID",N6,"") -> 1189 | D6: ISO | E6: A0 paper / DTF variant | F6: Two-thirds width | G6: Two-thirds width; full height. | H6: =IF(OR(M6<=0,N6<=0),"SKIPPED - NONPOSITIVE",IF(OR(M6<L6,N6<L6),"SKIPPED - BELOW MIN",IF(OR(M6>J6,N6>K6),"SKIPPED - EXCEEDS BASE",IF(COUNTIFS($M$2:M5,M6,$N$2:N5,N6)>0,"SKIPPED - DUPLICATE","VALID - GENERATED")))) -> VALID - GENERATED | I6: Generated inside the A0 paper/DTF envelope. Generated dimensions round down to whole millimetres; below-minimum or duplicate candidates are skipped. | J6: ='05-ISO Reference'!$B$5 -> 841 | K6: ='05-ISO Reference'!$C$5 -> 1189 | L6: ='01-Process Controls'!$G$5 -> 3 | M6: =ROUNDDOWN(J6*'04-Variant Rules'!$D$9,0) -> 560 | N6: =ROUNDDOWN(K6,0) -> 1189 | O6: 4
A7: A0-5 | B7: =IF(LEFT(H7,5)="VALID",M7,"") -> 630 | C7: =IF(LEFT(H7,5)="VALID",N7,"") -> 1189 | D7: ISO | E7: A0 paper / DTF variant | F7: Three-quarter width | G7: Three-quarter width; full height. | H7: =IF(OR(M7<=0,N7<=0),"SKIPPED - NONPOSITIVE",IF(OR(M7<L7,N7<L7),"SKIPPED - BELOW MIN",IF(OR(M7>J7,N7>K7),"SKIPPED - EXCEEDS BASE",IF(COUNTIFS($M$2:M6,M7,$N$2:N6,N7)>0,"SKIPPED - DUPLICATE","VALID - GENERATED")))) -> VALID - GENERATED | I7: Generated inside the A0 paper/DTF envelope. Generated dimensions round down to whole millimetres; below-minimum or duplicate candidates are skipped. | J7: ='05-ISO Reference'!$B$5 -> 841 | K7: ='05-ISO Reference'!$C$5 -> 1189 | L7: ='01-Process Controls'!$G$5 -> 3 | M7: =ROUNDDOWN(J7*'04-Variant Rules'!$D$10,0) -> 630 | N7: =ROUNDDOWN(K7,0) -> 1189 | O7: 5
A8: A0-6 | B8: =IF(LEFT(H8,5)="VALID",M8,"") -> 841 | C8: =IF(LEFT(H8,5)="VALID",N8,"") -> 594 | D8: ISO | E8: A0 paper / DTF variant | F8: Half height | G8: Full width; half height. | H8: =IF(OR(M8<=0,N8<=0),"SKIPPED - NONPOSITIVE",IF(OR(M8<L8,N8<L8),"SKIPPED - BELOW MIN",IF(OR(M8>J8,N8>K8),"SKIPPED - EXCEEDS BASE",IF(COUNTIFS($M$2:M7,M8,$N$2:N7,N8)>0,"SKIPPED - DUPLICATE","VALID - GENERATED")))) -> VALID - GENERATED | I8: Generated inside the A0 paper/DTF envelope. Generated dimensions round down to whole millimetres; below-minimum or duplicate candidates are skipped. | J8: ='05-ISO Reference'!$B$5 -> 841 | K8: ='05-ISO Reference'!$C$5 -> 1189 | L8: ='01-Process Controls'!$G$5 -> 3 | M8: =ROUNDDOWN(J8,0) -> 841 | N8: =ROUNDDOWN(K8*'04-Variant Rules'!$D$11,0) -> 594 | O8: 6
A9: A0-7 | B9: =IF(LEFT(H9,5)="VALID",M9,"") -> 841 | C9: =IF(LEFT(H9,5)="VALID",N9,"") -> 396 | D9: ISO | E9: A0 paper / DTF variant | F9: Third height | G9: Full width; one-third height. | H9: =IF(OR(M9<=0,N9<=0),"SKIPPED - NONPOSITIVE",IF(OR(M9<L9,N9<L9),"SKIPPED - BELOW MIN",IF(OR(M9>J9,N9>K9),"SKIPPED - EXCEEDS BASE",IF(COUNTIFS($M$2:M8,M9,$N$2:N8,N9)>0,"SKIPPED - DUPLICATE","VALID - GENERATED")))) -> VALID - GENERATED | I9: Generated inside the A0 paper/DTF envelope. Generated dimensions round down to whole millimetres; below-minimum or duplicate candidates are skipped. | J9: ='05-ISO Reference'!$B$5 -> 841 | K9: ='05-ISO Reference'!$C$5 -> 1189 | L9: ='01-Process Controls'!$G$5 -> 3 | M9: =ROUNDDOWN(J9,0) -> 841 | N9: =ROUNDDOWN(K9*'04-Variant Rules'!$D$12,0) -> 396 | O9: 7
A10: A0-8 | B10: =IF(LEFT(H10,5)="VALID",M10,"") -> 841 | C10: =IF(LEFT(H10,5)="VALID",N10,"") -> 297 | D10: ISO | E10: A0 paper / DTF variant | F10: Quarter height | G10: Full width; quarter height. | H10: =IF(OR(M10<=0,N10<=0),"SKIPPED - NONPOSITIVE",IF(OR(M10<L10,N10<L10),"SKIPPED - BELOW MIN",IF(OR(M10>J10,N10>K10),"SKIPPED - EXCEEDS BASE",IF(COUNTIFS($M$2:M9,M10,$N$2:N9,N10)>0,"SKIPPED - DUPLICATE","VALID - GENERATED")))) -> VALID - GENERATED | I10: Generated inside the A0 paper/DTF envelope. Generated dimensions round down to whole millimetres; below-minimum or duplicate candidates are skipped. | J10: ='05-ISO Reference'!$B$5 -> 841 | K10: ='05-ISO Reference'!$C$5 -> 1189 | L10: ='01-Process Controls'!$G$5 -> 3 | M10: =ROUNDDOWN(J10,0) -> 841 | N10: =ROUNDDOWN(K10*'04-Variant Rules'!$D$13,0) -> 297 | O10: 8
A11: A0-9 | B11: =IF(LEFT(H11,5)="VALID",M11,"") -> 841 | C11: =IF(LEFT(H11,5)="VALID",N11,"") -> 792 | D11: ISO | E11: A0 paper / DTF variant | F11: Two-thirds height | G11: Full width; two-thirds height. | H11: =IF(OR(M11<=0,N11<=0),"SKIPPED - NONPOSITIVE",IF(OR(M11<L11,N11<L11),"SKIPPED - BELOW MIN",IF(OR(M11>J11,N11>K11),"SKIPPED - EXCEEDS BASE",IF(COUNTIFS($M$2:M10,M11,$N$2:N10,N11)>0,"SKIPPED - DUPLICATE","VALID - GENERATED")))) -> VALID - GENERATED | I11: Generated inside the A0 paper/DTF envelope. Generated dimensions round down to whole millimetres; below-minimum or duplicate candidates are skipped. | J11: ='05-ISO Reference'!$B$5 -> 841 | K11: ='05-ISO Reference'!$C$5 -> 1189 | L11: ='01-Process Controls'!$G$5 -> 3 | M11: =ROUNDDOWN(J11,0) -> 841 | N11: =ROUNDDOWN(K11*'04-Variant Rules'!$D$14,0) -> 792 | O11: 9
A12: A0-10 | B12: =IF(LEFT(H12,5)="VALID",M12,"") -> 841 | C12: =IF(LEFT(H12,5)="VALID",N12,"") -> 891 | D12: ISO | E12: A0 paper / DTF variant | F12: Three-quarter height | G12: Full width; three-quarter height. | H12: =IF(OR(M12<=0,N12<=0),"SKIPPED - NONPOSITIVE",IF(OR(M12<L12,N12<L12),"SKIPPED - BELOW MIN",IF(OR(M12>J12,N12>K12),"SKIPPED - EXCEEDS BASE",IF(COUNTIFS($M$2:M11,M12,$N$2:N11,N12)>0,"SKIPPED - DUPLICATE","VALID - GENERATED")))) -> VALID - GENERATED | I12: Generated inside the A0 paper/DTF envelope. Generated dimensions round down to whole millimetres; below-minimum or duplicate candidates are skipped. | J12: ='05-ISO Reference'!$B$5 -> 841 | K12: ='05-ISO Reference'!$C$5 -> 1189 | L12: ='01-Process Controls'!$G$5 -> 3 | M12: =ROUNDDOWN(J12,0) -> 841 | N12: =ROUNDDOWN(K12*'04-Variant Rules'!$D$15,0) -> 891 | O12: 10
A13: A0-11 | B13: =IF(LEFT(H13,5)="VALID",M13,"") -> 420 | C13: =IF(LEFT(H13,5)="VALID",N13,"") -> 594 | D13: ISO | E13: A0 paper / DTF variant | F13: Half both | G13: Half width and half height. | H13: =IF(OR(M13<=0,N13<=0),"SKIPPED - NONPOSITIVE",IF(OR(M13<L13,N13<L13),"SKIPPED - BELOW MIN",IF(OR(M13>J13,N13>K13),"SKIPPED - EXCEEDS BASE",IF(COUNTIFS($M$2:M12,M13,$N$2:N12,N13)>0,"SKIPPED - DUPLICATE","VALID - GENERATED")))) -> VALID - GENERATED | I13: Generated inside the A0 paper/DTF envelope. Generated dimensions round down to whole millimetres; below-minimum or duplicate candidates are skipped. | J13: ='05-ISO Reference'!$B$5 -> 841 | K13: ='05-ISO Reference'!$C$5 -> 1189 | L13: ='01-Process Controls'!$G$5 -> 3 | M13: =ROUNDDOWN(J13*'04-Variant Rules'!$D$16,0) -> 420 | N13: =ROUNDDOWN(K13*'04-Variant Rules'!$E$16,0) -> 594 | O13: 11
A14: A0-12 | B14: =IF(LEFT(H14,5)="VALID",M14,"") -> 280 | C14: =IF(LEFT(H14,5)="VALID",N14,"") -> 396 | D14: ISO | E14: A0 paper / DTF variant | F14: Third both | G14: One-third width and height. | H14: =IF(OR(M14<=0,N14<=0),"SKIPPED - NONPOSITIVE",IF(OR(M14<L14,N14<L14),"SKIPPED - BELOW MIN",IF(OR(M14>J14,N14>K14),"SKIPPED - EXCEEDS BASE",IF(COUNTIFS($M$2:M13,M14,$N$2:N13,N14)>0,"SKIPPED - DUPLICATE","VALID - GENERATED")))) -> VALID - GENERATED | I14: Generated inside the A0 paper/DTF envelope. Generated dimensions round down to whole millimetres; below-minimum or duplicate candidates are skipped. | J14: ='05-ISO Reference'!$B$5 -> 841 | K14: ='05-ISO Reference'!$C$5 -> 1189 | L14: ='01-Process Controls'!$G$5 -> 3 | M14: =ROUNDDOWN(J14*'04-Variant Rules'!$D$17,0) -> 280 | N14: =ROUNDDOWN(K14*'04-Variant Rules'!$E$17,0) -> 396 | O14: 12
A15: A0-13 | B15: =IF(LEFT(H15,5)="VALID",M15,"") -> 210 | C15: =IF(LEFT(H15,5)="VALID",N15,"") -> 297 | D15: ISO | E15: A0 paper / DTF variant | F15: Quarter both | G15: Quarter width and height. | H15: =IF(OR(M15<=0,N15<=0),"SKIPPED - NONPOSITIVE",IF(OR(M15<L15,N15<L15),"SKIPPED - BELOW MIN",IF(OR(M15>J15,N15>K15),"SKIPPED - EXCEEDS BASE",IF(COUNTIFS($M$2:M14,M15,$N$2:N14,N15)>0,"SKIPPED - DUPLICATE","VALID - GENERATED")))) -> VALID - GENERATED | I15: Generated inside the A0 paper/DTF envelope. Generated dimensions round down to whole millimetres; below-minimum or duplicate candidates are skipped. | J15: ='05-ISO Reference'!$B$5 -> 841 | K15: ='05-ISO Reference'!$C$5 -> 1189 | L15: ='01-Process Controls'!$G$5 -> 3 | M15: =ROUNDDOWN(J15*'04-Variant Rules'!$D$18,0) -> 210 | N15: =ROUNDDOWN(K15*'04-Variant Rules'!$E$18,0) -> 297 | O15: 13
A16: A0-14 | B16: =IF(LEFT(H16,5)="VALID",M16,"") -> 420 | C16: =IF(LEFT(H16,5)="VALID",N16,"") -> 396 | D16: ISO | E16: A0 paper / DTF variant | F16: Half width x third height | G16: Mixed grid cell. | H16: =IF(OR(M16<=0,N16<=0),"SKIPPED - NONPOSITIVE",IF(OR(M16<L16,N16<L16),"SKIPPED - BELOW MIN",IF(OR(M16>J16,N16>K16),"SKIPPED - EXCEEDS BASE",IF(COUNTIFS($M$2:M15,M16,$N$2:N15,N16)>0,"SKIPPED - DUPLICATE","VALID - GENERATED")))) -> VALID - GENERATED | I16: Generated inside the A0 paper/DTF envelope. Generated dimensions round down to whole millimetres; below-minimum or duplicate candidates are skipped. | J16: ='05-ISO Reference'!$B$5 -> 841 | K16: ='05-ISO Reference'!$C$5 -> 1189 | L16: ='01-Process Controls'!$G$5 -> 3 | M16: =ROUNDDOWN(J16*'04-Variant Rules'!$D$19,0) -> 420 | N16: =ROUNDDOWN(K16*'04-Variant Rules'!$E$19,0) -> 396 | O16: 14
A17: A0-15 | B17: =IF(LEFT(H17,5)="VALID",M17,"") -> 280 | C17: =IF(LEFT(H17,5)="VALID",N17,"") -> 594 | D17: ISO | E17: A0 paper / DTF variant | F17: Third width x half height | G17: Mixed grid cell. | H17: =IF(OR(M17<=0,N17<=0),"SKIPPED - NONPOSITIVE",IF(OR(M17<L17,N17<L17),"SKIPPED - BELOW MIN",IF(OR(M17>J17,N17>K17),"SKIPPED - EXCEEDS BASE",IF(COUNTIFS($M$2:M16,M17,$N$2:N16,N17)>0,"SKIPPED - DUPLICATE","VALID - GENERATED")))) -> VALID - GENERATED | I17: Generated inside the A0 paper/DTF envelope. Generated dimensions round down to whole millimetres; below-minimum or duplicate candidates are skipped. | J17: ='05-ISO Reference'!$B$5 -> 841 | K17: ='05-ISO Reference'!$C$5 -> 1189 | L17: ='01-Process Controls'!$G$5 -> 3 | M17: =ROUNDDOWN(J17*'04-Variant Rules'!$D$20,0) -> 280 | N17: =ROUNDDOWN(K17*'04-Variant Rules'!$E$20,0) -> 594 | O17: 15
A18: A0-16 | B18: =IF(LEFT(H18,5)="VALID",M18,"") -> 420 | C18: =IF(LEFT(H18,5)="VALID",N18,"") -> 297 | D18: ISO | E18: A0 paper / DTF variant | F18: Half width x quarter height | G18: Mixed grid cell. | H18: =IF(OR(M18<=0,N18<=0),"SKIPPED - NONPOSITIVE",IF(OR(M18<L18,N18<L18),"SKIPPED - BELOW MIN",IF(OR(M18>J18,N18>K18),"SKIPPED - EXCEEDS BASE",IF(COUNTIFS($M$2:M17,M18,$N$2:N17,N18)>0,"SKIPPED - DUPLICATE","VALID - GENERATED")))) -> VALID - GENERATED | I18: Generated inside the A0 paper/DTF envelope. Generated dimensions round down to whole millimetres; below-minimum or duplicate candidates are skipped. | J18: ='05-ISO Reference'!$B$5 -> 841 | K18: ='05-ISO Reference'!$C$5 -> 1189 | L18: ='01-Process Controls'!$G$5 -> 3 | M18: =ROUNDDOWN(J18*'04-Variant Rules'!$D$21,0) -> 420 | N18: =ROUNDDOWN(K18*'04-Variant Rules'!$E$21,0) -> 297 | O18: 16
A19: A0-17 | B19: =IF(LEFT(H19,5)="VALID",M19,"") -> 210 | C19: =IF(LEFT(H19,5)="VALID",N19,"") -> 594 | D19: ISO | E19: A0 paper / DTF variant | F19: Quarter width x half height | G19: Mixed grid cell. | H19: =IF(OR(M19<=0,N19<=0),"SKIPPED - NONPOSITIVE",IF(OR(M19<L19,N19<L19),"SKIPPED - BELOW MIN",IF(OR(M19>J19,N19>K19),"SKIPPED - EXCEEDS BASE",IF(COUNTIFS($M$2:M18,M19,$N$2:N18,N19)>0,"SKIPPED - DUPLICATE","VALID - GENERATED")))) -> VALID - GENERATED | I19: Generated inside the A0 paper/DTF envelope. Generated dimensions round down to whole millimetres; below-minimum or duplicate candidates are skipped. | J19: ='05-ISO Reference'!$B$5 -> 841 | K19: ='05-ISO Reference'!$C$5 -> 1189 | L19: ='01-Process Controls'!$G$5 -> 3 | M19: =ROUNDDOWN(J19*'04-Variant Rules'!$D$22,0) -> 210 | N19: =ROUNDDOWN(K19*'04-Variant Rules'!$E$22,0) -> 594 | O19: 17
A20: A0-18 | B20: =IF(LEFT(H20,5)="VALID",M20,"") -> 560 | C20: =IF(LEFT(H20,5)="VALID",N20,"") -> 594 | D20: ISO | E20: A0 paper / DTF variant | F20: Two-thirds width x half height | G20: Mixed grid cell. | H20: =IF(OR(M20<=0,N20<=0),"SKIPPED - NONPOSITIVE",IF(OR(M20<L20,N20<L20),"SKIPPED - BELOW MIN",IF(OR(M20>J20,N20>K20),"SKIPPED - EXCEEDS BASE",IF(COUNTIFS($M$2:M19,M20,$N$2:N19,N20)>0,"SKIPPED - DUPLICATE","VALID - GENERATED")))) -> VALID - GENERATED | I20: Generated inside the A0 paper/DTF envelope. Generated dimensions round down to whole millimetres; below-minimum or duplicate candidates are skipped. | J20: ='05-ISO Reference'!$B$5 -> 841 | K20: ='05-ISO Reference'!$C$5 -> 1189 | L20: ='01-Process Controls'!$G$5 -> 3 | M20: =ROUNDDOWN(J20*'04-Variant Rules'!$D$23,0) -> 560 | N20: =ROUNDDOWN(K20*'04-Variant Rules'!$E$23,0) -> 594 | O20: 18
A21: A0-19 | B21: =IF(LEFT(H21,5)="VALID",M21,"") -> 420 | C21: =IF(LEFT(H21,5)="VALID",N21,"") -> 792 | D21: ISO | E21: A0 paper / DTF variant | F21: Half width x two-thirds height | G21: Mixed grid cell. | H21: =IF(OR(M21<=0,N21<=0),"SKIPPED - NONPOSITIVE",IF(OR(M21<L21,N21<L21),"SKIPPED - BELOW MIN",IF(OR(M21>J21,N21>K21),"SKIPPED - EXCEEDS BASE",IF(COUNTIFS($M$2:M20,M21,$N$2:N20,N21)>0,"SKIPPED - DUPLICATE","VALID - GENERATED")))) -> VALID - GENERATED | I21: Generated inside the A0 paper/DTF envelope. Generated dimensions round down to whole millimetres; below-minimum or duplicate candidates are skipped. | J21: ='05-ISO Reference'!$B$5 -> 841 | K21: ='05-ISO Reference'!$C$5 -> 1189 | L21: ='01-Process Controls'!$G$5 -> 3 | M21: =ROUNDDOWN(J21*'04-Variant Rules'!$D$24,0) -> 420 | N21: =ROUNDDOWN(K21*'04-Variant Rules'!$E$24,0) -> 792 | O21: 19
A22: A0-20 | B22: =IF(LEFT(H22,5)="VALID",M22,"") -> 630 | C22: =IF(LEFT(H22,5)="VALID",N22,"") -> 594 | D22: ISO | E22: A0 paper / DTF variant | F22: Three-quarter width x half height | G22: Mixed grid cell. | H22: =IF(OR(M22<=0,N22<=0),"SKIPPED - NONPOSITIVE",IF(OR(M22<L22,N22<L22),"SKIPPED - BELOW MIN",IF(OR(M22>J22,N22>K22),"SKIPPED - EXCEEDS BASE",IF(COUNTIFS($M$2:M21,M22,$N$2:N21,N22)>0,"SKIPPED - DUPLICATE","VALID - GENERATED")))) -> VALID - GENERATED | I22: Generated inside the A0 paper/DTF envelope. Generated dimensions round down to whole millimetres; below-minimum or duplicate candidates are skipped. | J22: ='05-ISO Reference'!$B$5 -> 841 | K22: ='05-ISO Reference'!$C$5 -> 1189 | L22: ='01-Process Controls'!$G$5 -> 3 | M22: =ROUNDDOWN(J22*'04-Variant Rules'!$D$25,0) -> 630 | N22: =ROUNDDOWN(K22*'04-Variant Rules'!$E$25,0) -> 594 | O22: 20
A23: A0-21 | B23: =IF(LEFT(H23,5)="VALID",M23,"") -> 420 | C23: =IF(LEFT(H23,5)="VALID",N23,"") -> 891 | D23: ISO | E23: A0 paper / DTF variant | F23: Half width x three-quarter height | G23: Mixed grid cell. | H23: =IF(OR(M23<=0,N23<=0),"SKIPPED - NONPOSITIVE",IF(OR(M23<L23,N23<L23),"SKIPPED - BELOW MIN",IF(OR(M23>J23,N23>K23),"SKIPPED - EXCEEDS BASE",IF(COUNTIFS($M$2:M22,M23,$N$2:N22,N23)>0,"SKIPPED - DUPLICATE","VALID - GENERATED")))) -> VALID - GENERATED | I23: Generated inside the A0 paper/DTF envelope. Generated dimensions round down to whole millimetres; below-minimum or duplicate candidates are skipped. | J23: ='05-ISO Reference'!$B$5 -> 841 | K23: ='05-ISO Reference'!$C$5 -> 1189 | L23: ='01-Process Controls'!$G$5 -> 3 | M23: =ROUNDDOWN(J23*'04-Variant Rules'!$D$26,0) -> 420 | N23: =ROUNDDOWN(K23*'04-Variant Rules'!$E$26,0) -> 891 | O23: 21
A24: A0-22 | B24: =IF(LEFT(H24,5)="VALID",M24,"") -> 798 | C24: =IF(LEFT(H24,5)="VALID",N24,"") -> 1129 | D24: ISO | E24: A0 paper / DTF variant | F24: Scale 95% | G24: Proportional inset without fixed millimetre subtraction. | H24: =IF(OR(M24<=0,N24<=0),"SKIPPED - NONPOSITIVE",IF(OR(M24<L24,N24<L24),"SKIPPED - BELOW MIN",IF(OR(M24>J24,N24>K24),"SKIPPED - EXCEEDS BASE",IF(COUNTIFS($M$2:M23,M24,$N$2:N23,N24)>0,"SKIPPED - DUPLICATE","VALID - GENERATED")))) -> VALID - GENERATED | I24: Generated inside the A0 paper/DTF envelope. Generated dimensions round down to whole millimetres; below-minimum or duplicate candidates are skipped. | J24: ='05-ISO Reference'!$B$5 -> 841 | K24: ='05-ISO Reference'!$C$5 -> 1189 | L24: ='01-Process Controls'!$G$5 -> 3 | M24: =ROUNDDOWN(J24*'04-Variant Rules'!$D$27,0) -> 798 | N24: =ROUNDDOWN(K24*'04-Variant Rules'!$E$27,0) -> 1129 | O24: 22
A25: A0-23 | B25: =IF(LEFT(H25,5)="VALID",M25,"") -> 756 | C25: =IF(LEFT(H25,5)="VALID",N25,"") -> 1070 | D25: ISO | E25: A0 paper / DTF variant | F25: Scale 90% | G25: Proportional scale. | H25: =IF(OR(M25<=0,N25<=0),"SKIPPED - NONPOSITIVE",IF(OR(M25<L25,N25<L25),"SKIPPED - BELOW MIN",IF(OR(M25>J25,N25>K25),"SKIPPED - EXCEEDS BASE",IF(COUNTIFS($M$2:M24,M25,$N$2:N24,N25)>0,"SKIPPED - DUPLICATE","VALID - GENERATED")))) -> VALID - GENERATED | I25: Generated inside the A0 paper/DTF envelope. Generated dimensions round down to whole millimetres; below-minimum or duplicate candidates are skipped. | J25: ='05-ISO Reference'!$B$5 -> 841 | K25: ='05-ISO Reference'!$C$5 -> 1189 | L25: ='01-Process Controls'!$G$5 -> 3 | M25: =ROUNDDOWN(J25*'04-Variant Rules'!$D$28,0) -> 756 | N25: =ROUNDDOWN(K25*'04-Variant Rules'!$E$28,0) -> 1070 | O25: 23
A26: A0-24 | B26: =IF(LEFT(H26,5)="VALID",M26,"") -> 714 | C26: =IF(LEFT(H26,5)="VALID",N26,"") -> 1010 | D26: ISO | E26: A0 paper / DTF variant | F26: Scale 85% | G26: Proportional scale. | H26: =IF(OR(M26<=0,N26<=0),"SKIPPED - NONPOSITIVE",IF(OR(M26<L26,N26<L26),"SKIPPED - BELOW MIN",IF(OR(M26>J26,N26>K26),"SKIPPED - EXCEEDS BASE",IF(COUNTIFS($M$2:M25,M26,$N$2:N25,N26)>0,"SKIPPED - DUPLICATE","VALID - GENERATED")))) -> VALID - GENERATED | I26: Generated inside the A0 paper/DTF envelope. Generated dimensions round down to whole millimetres; below-minimum or duplicate candidates are skipped. | J26: ='05-ISO Reference'!$B$5 -> 841 | K26: ='05-ISO Reference'!$C$5 -> 1189 | L26: ='01-Process Controls'!$G$5 -> 3 | M26: =ROUNDDOWN(J26*'04-Variant Rules'!$D$29,0) -> 714 | N26: =ROUNDDOWN(K26*'04-Variant Rules'!$E$29,0) -> 1010 | O26: 24
A27: A0-25 | B27: =IF(LEFT(H27,5)="VALID",M27,"") -> 672 | C27: =IF(LEFT(H27,5)="VALID",N27,"") -> 951 | D27: ISO | E27: A0 paper / DTF variant | F27: Scale 80% | G27: Proportional scale. | H27: =IF(OR(M27<=0,N27<=0),"SKIPPED - NONPOSITIVE",IF(OR(M27<L27,N27<L27),"SKIPPED - BELOW MIN",IF(OR(M27>J27,N27>K27),"SKIPPED - EXCEEDS BASE",IF(COUNTIFS($M$2:M26,M27,$N$2:N26,N27)>0,"SKIPPED - DUPLICATE","VALID - GENERATED")))) -> VALID - GENERATED | I27: Generated inside the A0 paper/DTF envelope. Generated dimensions round down to whole millimetres; below-minimum or duplicate candidates are skipped. | J27: ='05-ISO Reference'!$B$5 -> 841 | K27: ='05-ISO Reference'!$C$5 -> 1189 | L27: ='01-Process Controls'!$G$5 -> 3 | M27: =ROUNDDOWN(J27*'04-Variant Rules'!$D$30,0) -> 672 | N27: =ROUNDDOWN(K27*'04-Variant Rules'!$E$30,0) -> 951 | O27: 25
A28: A0-26 | B28: =IF(LEFT(H28,5)="VALID",M28,"") -> 630 | C28: =IF(LEFT(H28,5)="VALID",N28,"") -> 891 | D28: ISO | E28: A0 paper / DTF variant | F28: Scale 75% | G28: Proportional scale. | H28: =IF(OR(M28<=0,N28<=0),"SKIPPED - NONPOSITIVE",IF(OR(M28<L28,N28<L28),"SKIPPED - BELOW MIN",IF(OR(M28>J28,N28>K28),"SKIPPED - EXCEEDS BASE",IF(COUNTIFS($M$2:M27,M28,$N$2:N27,N28)>0,"SKIPPED - DUPLICATE","VALID - GENERATED")))) -> VALID - GENERATED | I28: Generated inside the A0 paper/DTF envelope. Generated dimensions round down to whole millimetres; below-minimum or duplicate candidates are skipped. | J28: ='05-ISO Reference'!$B$5 -> 841 | K28: ='05-ISO Reference'!$C$5 -> 1189 | L28: ='01-Process Controls'!$G$5 -> 3 | M28: =ROUNDDOWN(J28*'04-Variant Rules'!$D$31,0) -> 630 | N28: =ROUNDDOWN(K28*'04-Variant Rules'!$E$31,0) -> 891 | O28: 26
A29: A0-27 | B29: =IF(LEFT(H29,5)="VALID",M29,"") -> 588 | C29: =IF(LEFT(H29,5)="VALID",N29,"") -> 832 | D29: ISO | E29: A0 paper / DTF variant | F29: Scale 70% | G29: Proportional scale. | H29: =IF(OR(M29<=0,N29<=0),"SKIPPED - NONPOSITIVE",IF(OR(M29<L29,N29<L29),"SKIPPED - BELOW MIN",IF(OR(M29>J29,N29>K29),"SKIPPED - EXCEEDS BASE",IF(COUNTIFS($M$2:M28,M29,$N$2:N28,N29)>0,"SKIPPED - DUPLICATE","VALID - GENERATED")))) -> VALID - GENERATED | I29: Generated inside the A0 paper/DTF envelope. Generated dimensions round down to whole millimetres; below-minimum or duplicate candidates are skipped. | J29: ='05-ISO Reference'!$B$5 -> 841 | K29: ='05-ISO Reference'!$C$5 -> 1189 | L29: ='01-Process Controls'!$G$5 -> 3 | M29: =ROUNDDOWN(J29*'04-Variant Rules'!$D$32,0) -> 588 | N29: =ROUNDDOWN(K29*'04-Variant Rules'!$E$32,0) -> 832 | O29: 27
A30: A0-28 | B30: =IF(LEFT(H30,5)="VALID",M30,"") -> 560 | C30: =IF(LEFT(H30,5)="VALID",N30,"") -> 792 | D30: ISO | E30: A0 paper / DTF variant | F30: Scale 66.67% | G30: Proportional scale. | H30: =IF(OR(M30<=0,N30<=0),"SKIPPED - NONPOSITIVE",IF(OR(M30<L30,N30<L30),"SKIPPED - BELOW MIN",IF(OR(M30>J30,N30>K30),"SKIPPED - EXCEEDS BASE",IF(COUNTIFS($M$2:M29,M30,$N$2:N29,N30)>0,"SKIPPED - DUPLICATE","VALID - GENERATED")))) -> VALID - GENERATED | I30: Generated inside the A0 paper/DTF envelope. Generated dimensions round down to whole millimetres; below-minimum or duplicate candidates are skipped. | J30: ='05-ISO Reference'!$B$5 -> 841 | K30: ='05-ISO Reference'!$C$5 -> 1189 | L30: ='01-Process Controls'!$G$5 -> 3 | M30: =ROUNDDOWN(J30*'04-Variant Rules'!$D$33,0) -> 560 | N30: =ROUNDDOWN(K30*'04-Variant Rules'!$E$33,0) -> 792 | O30: 28
A31: A0-29 | B31: =IF(LEFT(H31,5)="VALID",M31,"") -> 504 | C31: =IF(LEFT(H31,5)="VALID",N31,"") -> 713 | D31: ISO | E31: A0 paper / DTF variant | F31: Scale 60% | G31: Proportional scale. | H31: =IF(OR(M31<=0,N31<=0),"SKIPPED - NONPOSITIVE",IF(OR(M31<L31,N31<L31),"SKIPPED - BELOW MIN",IF(OR(M31>J31,N31>K31),"SKIPPED - EXCEEDS BASE",IF(COUNTIFS($M$2:M30,M31,$N$2:N30,N31)>0,"SKIPPED - DUPLICATE","VALID - GENERATED")))) -> VALID - GENERATED | I31: Generated inside the A0 paper/DTF envelope. Generated dimensions round down to whole millimetres; below-minimum or duplicate candidates are skipped. | J31: ='05-ISO Reference'!$B$5 -> 841 | K31: ='05-ISO Reference'!$C$5 -> 1189 | L31: ='01-Process Controls'!$G$5 -> 3 | M31: =ROUNDDOWN(J31*'04-Variant Rules'!$D$34,0) -> 504 | N31: =ROUNDDOWN(K31*'04-Variant Rules'!$E$34,0) -> 713 | O31: 29
A32: A0-30 | B32: =IF(LEFT(H32,5)="VALID",M32,"") -> 462 | C32: =IF(LEFT(H32,5)="VALID",N32,"") -> 653 | D32: ISO | E32: A0 paper / DTF variant | F32: Scale 55% | G32: Proportional scale. | H32: =IF(OR(M32<=0,N32<=0),"SKIPPED - NONPOSITIVE",IF(OR(M32<L32,N32<L32),"SKIPPED - BELOW MIN",IF(OR(M32>J32,N32>K32),"SKIPPED - EXCEEDS BASE",IF(COUNTIFS($M$2:M31,M32,$N$2:N31,N32)>0,"SKIPPED - DUPLICATE","VALID - GENERATED")))) -> VALID - GENERATED | I32: Generated inside the A0 paper/DTF envelope. Generated dimensions round down to whole millimetres; below-minimum or duplicate candidates are skipped. | J32: ='05-ISO Reference'!$B$5 -> 841 | K32: ='05-ISO Reference'!$C$5 -> 1189 | L32: ='01-Process Controls'!$G$5 -> 3 | M32: =ROUNDDOWN(J32*'04-Variant Rules'!$D$35,0) -> 462 | N32: =ROUNDDOWN(K32*'04-Variant Rules'!$E$35,0) -> 653 | O32: 30
A33: A0-31 | B33: =IF(LEFT(H33,5)="VALID",M33,"") -> 378 | C33: =IF(LEFT(H33,5)="VALID",N33,"") -> 535 | D33: ISO | E33: A0 paper / DTF variant | F33: Scale 45% | G33: Proportional scale. | H33: =IF(OR(M33<=0,N33<=0),"SKIPPED - NONPOSITIVE",IF(OR(M33<L33,N33<L33),"SKIPPED - BELOW MIN",IF(OR(M33>J33,N33>K33),"SKIPPED - EXCEEDS BASE",IF(COUNTIFS($M$2:M32,M33,$N$2:N32,N33)>0,"SKIPPED - DUPLICATE","VALID - GENERATED")))) -> VALID - GENERATED | I33: Generated inside the A0 paper/DTF envelope. Generated dimensions round down to whole millimetres; below-minimum or duplicate candidates are skipped. | J33: ='05-ISO Reference'!$B$5 -> 841 | K33: ='05-ISO Reference'!$C$5 -> 1189 | L33: ='01-Process Controls'!$G$5 -> 3 | M33: =ROUNDDOWN(J33*'04-Variant Rules'!$D$36,0) -> 378 | N33: =ROUNDDOWN(K33*'04-Variant Rules'!$E$36,0) -> 535 | O33: 31
A34: A0-32 | B34: =IF(LEFT(H34,5)="VALID",M34,"") -> 336 | C34: =IF(LEFT(H34,5)="VALID",N34,"") -> 475 | D34: ISO | E34: A0 paper / DTF variant | F34: Scale 40% | G34: Proportional scale. | H34: =IF(OR(M34<=0,N34<=0),"SKIPPED - NONPOSITIVE",IF(OR(M34<L34,N34<L34),"SKIPPED - BELOW MIN",IF(OR(M34>J34,N34>K34),"SKIPPED - EXCEEDS BASE",IF(COUNTIFS($M$2:M33,M34,$N$2:N33,N34)>0,"SKIPPED - DUPLICATE","VALID - GENERATED")))) -> VALID - GENERATED | I34: Generated inside the A0 paper/DTF envelope. Generated dimensions round down to whole millimetres; below-minimum or duplicate candidates are skipped. | J34: ='05-ISO Reference'!$B$5 -> 841 | K34: ='05-ISO Reference'!$C$5 -> 1189 | L34: ='01-Process Controls'!$G$5 -> 3 | M34: =ROUNDDOWN(J34*'04-Variant Rules'!$D$37,0) -> 336 | N34: =ROUNDDOWN(K34*'04-Variant Rules'!$E$37,0) -> 475 | O34: 32
A35: A0-33 | B35: =IF(LEFT(H35,5)="VALID",M35,"") -> 294 | C35: =IF(LEFT(H35,5)="VALID",N35,"") -> 416 | D35: ISO | E35: A0 paper / DTF variant | F35: Scale 35% | G35: Proportional scale. | H35: =IF(OR(M35<=0,N35<=0),"SKIPPED - NONPOSITIVE",IF(OR(M35<L35,N35<L35),"SKIPPED - BELOW MIN",IF(OR(M35>J35,N35>K35),"SKIPPED - EXCEEDS BASE",IF(COUNTIFS($M$2:M34,M35,$N$2:N34,N35)>0,"SKIPPED - DUPLICATE","VALID - GENERATED")))) -> VALID - GENERATED | I35: Generated inside the A0 paper/DTF envelope. Generated dimensions round down to whole millimetres; below-minimum or duplicate candidates are skipped. | J35: ='05-ISO Reference'!$B$5 -> 841 | K35: ='05-ISO Reference'!$C$5 -> 1189 | L35: ='01-Process Controls'!$G$5 -> 3 | M35: =ROUNDDOWN(J35*'04-Variant Rules'!$D$38,0) -> 294 | N35: =ROUNDDOWN(K35*'04-Variant Rules'!$E$38,0) -> 416 | O35: 33
A36: A0-34 | B36: =IF(LEFT(H36,5)="VALID",M36,"") -> 252 | C36: =IF(LEFT(H36,5)="VALID",N36,"") -> 356 | D36: ISO | E36: A0 paper / DTF variant | F36: Scale 30% | G36: Proportional scale. | H36: =IF(OR(M36<=0,N36<=0),"SKIPPED - NONPOSITIVE",IF(OR(M36<L36,N36<L36),"SKIPPED - BELOW MIN",IF(OR(M36>J36,N36>K36),"SKIPPED - EXCEEDS BASE",IF(COUNTIFS($M$2:M35,M36,$N$2:N35,N36)>0,"SKIPPED - DUPLICATE","VALID - GENERATED")))) -> VALID - GENERATED | I36: Generated inside the A0 paper/DTF envelope. Generated dimensions round down to whole millimetres; below-minimum or duplicate candidates are skipped. | J36: ='05-ISO Reference'!$B$5 -> 841 | K36: ='05-ISO Reference'!$C$5 -> 1189 | L36: ='01-Process Controls'!$G$5 -> 3 | M36: =ROUNDDOWN(J36*'04-Variant Rules'!$D$39,0) -> 252 | N36: =ROUNDDOWN(K36*'04-Variant Rules'!$E$39,0) -> 356 | O36: 34
A37: A0-35 | B37: =IF(LEFT(H37,5)="VALID",M37,"") -> 168 | C37: =IF(LEFT(H37,5)="VALID",N37,"") -> 237 | D37: ISO | E37: A0 paper / DTF variant | F37: Scale 20% | G37: Proportional scale. | H37: =IF(OR(M37<=0,N37<=0),"SKIPPED - NONPOSITIVE",IF(OR(M37<L37,N37<L37),"SKIPPED - BELOW MIN",IF(OR(M37>J37,N37>K37),"SKIPPED - EXCEEDS BASE",IF(COUNTIFS($M$2:M36,M37,$N$2:N36,N37)>0,"SKIPPED - DUPLICATE","VALID - GENERATED")))) -> VALID - GENERATED | I37: Generated inside the A0 paper/DTF envelope. Generated dimensions round down to whole millimetres; below-minimum or duplicate candidates are skipped. | J37: ='05-ISO Reference'!$B$5 -> 841 | K37: ='05-ISO Reference'!$C$5 -> 1189 | L37: ='01-Process Controls'!$G$5 -> 3 | M37: =ROUNDDOWN(J37*'04-Variant Rules'!$D$40,0) -> 168 | N37: =ROUNDDOWN(K37*'04-Variant Rules'!$E$40,0) -> 237 | O37: 35
A38: A0-36 | B38: =IF(LEFT(H38,5)="VALID",M38,"") -> 126 | C38: =IF(LEFT(H38,5)="VALID",N38,"") -> 178 | D38: ISO | E38: A0 paper / DTF variant | F38: Scale 15% | G38: Proportional scale; may be skipped for very small bases. | H38: =IF(OR(M38<=0,N38<=0),"SKIPPED - NONPOSITIVE",IF(OR(M38<L38,N38<L38),"SKIPPED - BELOW MIN",IF(OR(M38>J38,N38>K38),"SKIPPED - EXCEEDS BASE",IF(COUNTIFS($M$2:M37,M38,$N$2:N37,N38)>0,"SKIPPED - DUPLICATE","VALID - GENERATED")))) -> VALID - GENERATED | I38: Generated inside the A0 paper/DTF envelope. Generated dimensions round down to whole millimetres; below-minimum or duplicate candidates are skipped. | J38: ='05-ISO Reference'!$B$5 -> 841 | K38: ='05-ISO Reference'!$C$5 -> 1189 | L38: ='01-Process Controls'!$G$5 -> 3 | M38: =ROUNDDOWN(J38*'04-Variant Rules'!$D$41,0) -> 126 | N38: =ROUNDDOWN(K38*'04-Variant Rules'!$E$41,0) -> 178 | O38: 36
A39: A0-37 | B39: =IF(LEFT(H39,5)="VALID",M39,"") -> 841 | C39: =IF(LEFT(H39,5)="VALID",N39,"") -> 841 | D39: ISO | E39: A0 paper / DTF variant | F39: Square 100% | G39: Largest square inside the base. | H39: =IF(OR(M39<=0,N39<=0),"SKIPPED - NONPOSITIVE",IF(OR(M39<L39,N39<L39),"SKIPPED - BELOW MIN",IF(OR(M39>J39,N39>K39),"SKIPPED - EXCEEDS BASE",IF(COUNTIFS($M$2:M38,M39,$N$2:N38,N39)>0,"SKIPPED - DUPLICATE","VALID - GENERATED")))) -> VALID - GENERATED | I39: Generated inside the A0 paper/DTF envelope. Generated dimensions round down to whole millimetres; below-minimum or duplicate candidates are skipped. | J39: ='05-ISO Reference'!$B$5 -> 841 | K39: ='05-ISO Reference'!$C$5 -> 1189 | L39: ='01-Process Controls'!$G$5 -> 3 | M39: =ROUNDDOWN(MIN(J39,K39)*'04-Variant Rules'!$D$42,0) -> 841 | N39: =ROUNDDOWN(MIN(J39,K39)*'04-Variant Rules'!$D$42,0) -> 841 | O39: 37
A40: A0-38 | B40: =IF(LEFT(H40,5)="VALID",M40,"") -> 756 | C40: =IF(LEFT(H40,5)="VALID",N40,"") -> 756 | D40: ISO | E40: A0 paper / DTF variant | F40: Square 90% | G40: Square based on the shorter side. | H40: =IF(OR(M40<=0,N40<=0),"SKIPPED - NONPOSITIVE",IF(OR(M40<L40,N40<L40),"SKIPPED - BELOW MIN",IF(OR(M40>J40,N40>K40),"SKIPPED - EXCEEDS BASE",IF(COUNTIFS($M$2:M39,M40,$N$2:N39,N40)>0,"SKIPPED - DUPLICATE","VALID - GENERATED")))) -> VALID - GENERATED | I40: Generated inside the A0 paper/DTF envelope. Generated dimensions round down to whole millimetres; below-minimum or duplicate candidates are skipped. | J40: ='05-ISO Reference'!$B$5 -> 841 | K40: ='05-ISO Reference'!$C$5 -> 1189 | L40: ='01-Process Controls'!$G$5 -> 3 | M40: =ROUNDDOWN(MIN(J40,K40)*'04-Variant Rules'!$D$43,0) -> 756 | N40: =ROUNDDOWN(MIN(J40,K40)*'04-Variant Rules'!$D$43,0) -> 756 | O40: 38
...

Sheet 03-POD Product Guide
A1: POD Product, Machine and Apparel Presets - A/B Codes Used for DTF
A2: DTF garment prints use the A/B entries in 02-Printing Size directly. All dimensions, including LCCO2, round down to whole millimetres. The apparel section below chooses the lowest full A/B paper code that fits each target position after applying a minimum starting code. Verify every final SKU with the supplier template, actual garment and heat-press setup.
A3: DTF rule: select the A/B base printing_size code itself. The base code is the full transfer size; for example A3 = A3 Full = 297 x 420 mm. Artwork may sit within the paper canvas and does not have to touch every edge.
A4: preset_code | B4: process_code | C4: product_or_use | D4: placement_or_shape | E4: width_mm | F4: height_mm | G4: preset_basis | H4: production_note | I4: source_url | J4: validation_status | K4: verify_before_production
A41: UV | B41: UV | C41: Nominal full bed | D41: Flatbed | E41: =ROUNDDOWN('01-Process Controls'!$D$7,0) -> 600 | F41: =ROUNDDOWN('01-Process Controls'!$E$7,0) -> 900 | G41: Machine-derived | H41: Nominal bed from process controls; fixtures may reduce this. | I41: https://mimaki.com/product/inkjet/i-flat/ujf-6042mkII-e/specification.html | J41: =IF(OR(E41<=0,F41<=0),"ERROR - NONPOSITIVE",IF(OR(E41<'01-Process Controls'!$G$7,F41<'01-Process Controls'!$G$7),"ERROR - BELOW MIN",IF(OR(AND(E41<='01-Process Controls'!$D$7-2*'01-Process Controls'!$H$7,F41<='01-Process Controls'!$E$7-2*'01-Process Controls'!$H$7),AND(E41<='01-Process Controls'!$E$7-2*'01-Process Controls'!$H$7,F41<='01-Process Controls'!$D$7-2*'01-Process Controls'!$H$7)),"VALID - SAFE",IF(OR(AND(E41<='01-Process Controls'!$D$7,F41<='01-Process Controls'!$E$7),AND(E41<='01-Process Controls'!$E$7,F41<='01-Process Controls'!$D$7)),"VALID - NOMINAL EDGE","ERROR - EXCEEDS BED")))) -> VALID - NOMINAL EDGE | K41: YES
A42: UV-1 | B42: UV | C42: Safe full bed | D42: Flatbed | E42: =ROUNDDOWN(MAX(1,'01-Process Controls'!$D$7-2*'01-Process Controls'!$H$7),0) -> 580 | F42: =ROUNDDOWN(MAX(1,'01-Process Controls'!$E$7-2*'01-Process Controls'!$H$7),0) -> 880 | G42: Machine-derived | H42: Configured safety margin applied on all sides. | I42: https://help.printful.com/hc/en-us/articles/10720620016540-What-is-the-safe-print-area | J42: =IF(OR(E42<=0,F42<=0),"ERROR - NONPOSITIVE",IF(OR(E42<'01-Process Controls'!$G$7,F42<'01-Process Controls'!$G$7),"ERROR - BELOW MIN",IF(OR(AND(E42<='01-Process Controls'!$D$7-2*'01-Process Controls'!$H$7,F42<='01-Process Controls'!$E$7-2*'01-Process Controls'!$H$7),AND(E42<='01-Process Controls'!$E$7-2*'01-Process Controls'!$H$7,F42<='01-Process Controls'!$D$7-2*'01-Process Controls'!$H$7)),"VALID - SAFE",IF(OR(AND(E42<='01-Process Controls'!$D$7,F42<='01-Process Controls'!$E$7),AND(E42<='01-Process Controls'!$E$7,F42<='01-Process Controls'!$D$7)),"VALID - NOMINAL EDGE","ERROR - EXCEEDS BED")))) -> VALID - SAFE | K42: YES
A43: UV-2 | B43: UV | C43: Half bed | D43: Landscape panel | E43: =ROUNDDOWN('01-Process Controls'!$D$7,0) -> 600 | F43: =ROUNDDOWN(ROUND('01-Process Controls'!$E$7/2,2),0) -> 450 | G43: Machine-derived | H43: Full width and half bed length. | J43: =IF(OR(E43<=0,F43<=0),"ERROR - NONPOSITIVE",IF(OR(E43<'01-Process Controls'!$G$7,F43<'01-Process Controls'!$G$7),"ERROR - BELOW MIN",IF(OR(AND(E43<='01-Process Controls'!$D$7-2*'01-Process Controls'!$H$7,F43<='01-Process Controls'!$E$7-2*'01-Process Controls'!$H$7),AND(E43<='01-Process Controls'!$E$7-2*'01-Process Controls'!$H$7,F43<='01-Process Controls'!$D$7-2*'01-Process Controls'!$H$7)),"VALID - SAFE",IF(OR(AND(E43<='01-Process Controls'!$D$7,F43<='01-Process Controls'!$E$7),AND(E43<='01-Process Controls'!$E$7,F43<='01-Process Controls'!$D$7)),"VALID - NOMINAL EDGE","ERROR - EXCEEDS BED")))) -> VALID - SAFE | K43: YES
A44: UV-3 | B44: UV | C44: A2 | D44: Portrait | E44: 420 | F44: 594 | G44: ISO-based | H44: Check actual bed/jig orientation. | I44: https://www.iso.org/standard/36631.html | J44: =IF(OR(E44<=0,F44<=0),"ERROR - NONPOSITIVE",IF(OR(E44<'01-Process Controls'!$G$7,F44<'01-Process Controls'!$G$7),"ERROR - BELOW MIN",IF(OR(AND(E44<='01-Process Controls'!$D$7-2*'01-Process Controls'!$H$7,F44<='01-Process Controls'!$E$7-2*'01-Process Controls'!$H$7),AND(E44<='01-Process Controls'!$E$7-2*'01-Process Controls'!$H$7,F44<='01-Process Controls'!$D$7-2*'01-Process Controls'!$H$7)),"VALID - SAFE",IF(OR(AND(E44<='01-Process Controls'!$D$7,F44<='01-Process Controls'!$E$7),AND(E44<='01-Process Controls'!$E$7,F44<='01-Process Controls'!$D$7)),"VALID - NOMINAL EDGE","ERROR - EXCEEDS BED")))) -> VALID - SAFE | K44: YES
A45: UV-4 | B45: UV | C45: A2 | D45: Landscape | E45: 594 | F45: 420 | G45: ISO-based | H45: Check actual bed/jig orientation. | I45: https://www.iso.org/standard/36631.html | J45: =IF(OR(E45<=0,F45<=0),"ERROR - NONPOSITIVE",IF(OR(E45<'01-Process Controls'!$G$7,F45<'01-Process Controls'!$G$7),"ERROR - BELOW MIN",IF(OR(AND(E45<='01-Process Controls'!$D$7-2*'01-Process Controls'!$H$7,F45<='01-Process Controls'!$E$7-2*'01-Process Controls'!$H$7),AND(E45<='01-Process Controls'!$E$7-2*'01-Process Controls'!$H$7,F45<='01-Process Controls'!$D$7-2*'01-Process Controls'!$H$7)),"VALID - SAFE",IF(OR(AND(E45<='01-Process Controls'!$D$7,F45<='01-Process Controls'!$E$7),AND(E45<='01-Process Controls'!$E$7,F45<='01-Process Controls'!$D$7)),"VALID - NOMINAL EDGE","ERROR - EXCEEDS BED")))) -> VALID - SAFE | K45: YES
A46: UV-5 | B46: UV | C46: A3 | D46: Portrait | E46: 297 | F46: 420 | G46: ISO-based | I46: https://www.iso.org/standard/36631.html | J46: =IF(OR(E46<=0,F46<=0),"ERROR - NONPOSITIVE",IF(OR(E46<'01-Process Controls'!$G$7,F46<'01-Process Controls'!$G$7),"ERROR - BELOW MIN",IF(OR(AND(E46<='01-Process Controls'!$D$7-2*'01-Process Controls'!$H$7,F46<='01-Process Controls'!$E$7-2*'01-Process Controls'!$H$7),AND(E46<='01-Process Controls'!$E$7-2*'01-Process Controls'!$H$7,F46<='01-Process Controls'!$D$7-2*'01-Process Controls'!$H$7)),"VALID - SAFE",IF(OR(AND(E46<='01-Process Controls'!$D$7,F46<='01-Process Controls'!$E$7),AND(E46<='01-Process Controls'!$E$7,F46<='01-Process Controls'!$D$7)),"VALID - NOMINAL EDGE","ERROR - EXCEEDS BED")))) -> VALID - SAFE | K46: YES
A47: UV-6 | B47: UV | C47: A4 | D47: Portrait | E47: 210 | F47: 297 | G47: ISO-based | I47: https://www.iso.org/standard/36631.html | J47: =IF(OR(E47<=0,F47<=0),"ERROR - NONPOSITIVE",IF(OR(E47<'01-Process Controls'!$G$7,F47<'01-Process Controls'!$G$7),"ERROR - BELOW MIN",IF(OR(AND(E47<='01-Process Controls'!$D$7-2*'01-Process Controls'!$H$7,F47<='01-Process Controls'!$E$7-2*'01-Process Controls'!$H$7),AND(E47<='01-Process Controls'!$E$7-2*'01-Process Controls'!$H$7,F47<='01-Process Controls'!$D$7-2*'01-Process Controls'!$H$7)),"VALID - SAFE",IF(OR(AND(E47<='01-Process Controls'!$D$7,F47<='01-Process Controls'!$E$7),AND(E47<='01-Process Controls'!$E$7,F47<='01-Process Controls'!$D$7)),"VALID - NOMINAL EDGE","ERROR - EXCEEDS BED")))) -> VALID - SAFE | K47: YES
A48: UV-7 | B48: UV | C48: A5 | D48: Portrait | E48: 148 | F48: 210 | G48: ISO-based | I48: https://www.iso.org/standard/36631.html | J48: =IF(OR(E48<=0,F48<=0),"ERROR - NONPOSITIVE",IF(OR(E48<'01-Process Controls'!$G$7,F48<'01-Process Controls'!$G$7),"ERROR - BELOW MIN",IF(OR(AND(E48<='01-Process Controls'!$D$7-2*'01-Process Controls'!$H$7,F48<='01-Process Controls'!$E$7-2*'01-Process Controls'!$H$7),AND(E48<='01-Process Controls'!$E$7-2*'01-Process Controls'!$H$7,F48<='01-Process Controls'!$D$7-2*'01-Process Controls'!$H$7)),"VALID - SAFE",IF(OR(AND(E48<='01-Process Controls'!$D$7,F48<='01-Process Controls'!$E$7),AND(E48<='01-Process Controls'!$E$7,F48<='01-Process Controls'!$D$7)),"VALID - NOMINAL EDGE","ERROR - EXCEEDS BED")))) -> VALID - SAFE | K48: YES
A49: UV-8 | B49: UV | C49: Rigid panel | D49: Square | E49: 300 | F49: 300 | G49: Shop starting preset | H49: Measure substrate and jig. | J49: =IF(OR(E49<=0,F49<=0),"ERROR - NONPOSITIVE",IF(OR(E49<'01-Process Controls'!$G$7,F49<'01-Process Controls'!$G$7),"ERROR - BELOW MIN",IF(OR(AND(E49<='01-Process Controls'!$D$7-2*'01-Process Controls'!$H$7,F49<='01-Process Controls'!$E$7-2*'01-Process Controls'!$H$7),AND(E49<='01-Process Controls'!$E$7-2*'01-Process Controls'!$H$7,F49<='01-Process Controls'!$D$7-2*'01-Process Controls'!$H$7)),"VALID - SAFE",IF(OR(AND(E49<='01-Process Controls'!$D$7,F49<='01-Process Controls'!$E$7),AND(E49<='01-Process Controls'!$E$7,F49<='01-Process Controls'!$D$7)),"VALID - NOMINAL EDGE","ERROR - EXCEEDS BED")))) -> VALID - SAFE | K49: YES
A50: UV-9 | B50: UV | C50: Rigid panel | D50: Square | E50: 250 | F50: 250 | G50: Shop starting preset | H50: Measure substrate and jig. | J50: =IF(OR(E50<=0,F50<=0),"ERROR - NONPOSITIVE",IF(OR(E50<'01-Process Controls'!$G$7,F50<'01-Process Controls'!$G$7),"ERROR - BELOW MIN",IF(OR(AND(E50<='01-Process Controls'!$D$7-2*'01-Process Controls'!$H$7,F50<='01-Process Controls'!$E$7-2*'01-Process Controls'!$H$7),AND(E50<='01-Process Controls'!$E$7-2*'01-Process Controls'!$H$7,F50<='01-Process Controls'!$D$7-2*'01-Process Controls'!$H$7)),"VALID - SAFE",IF(OR(AND(E50<='01-Process Controls'!$D$7,F50<='01-Process Controls'!$E$7),AND(E50<='01-Process Controls'!$E$7,F50<='01-Process Controls'!$D$7)),"VALID - NOMINAL EDGE","ERROR - EXCEEDS BED")))) -> VALID - SAFE | K50: YES
A51: UV-10 | B51: UV | C51: Rigid panel | D51: Square | E51: 200 | F51: 200 | G51: Shop starting preset | H51: Measure substrate and jig. | J51: =IF(OR(E51<=0,F51<=0),"ERROR - NONPOSITIVE",IF(OR(E51<'01-Process Controls'!$G$7,F51<'01-Process Controls'!$G$7),"ERROR - BELOW MIN",IF(OR(AND(E51<='01-Process Controls'!$D$7-2*'01-Process Controls'!$H$7,F51<='01-Process Controls'!$E$7-2*'01-Process Controls'!$H$7),AND(E51<='01-Process Controls'!$E$7-2*'01-Process Controls'!$H$7,F51<='01-Process Controls'!$D$7-2*'01-Process Controls'!$H$7)),"VALID - SAFE",IF(OR(AND(E51<='01-Process Controls'!$D$7,F51<='01-Process Controls'!$E$7),AND(E51<='01-Process Controls'!$E$7,F51<='01-Process Controls'!$D$7)),"VALID - NOMINAL EDGE","ERROR - EXCEEDS BED")))) -> VALID - SAFE | K51: YES
A52: UV-11 | B52: UV | C52: Rigid panel | D52: Square | E52: 150 | F52: 150 | G52: Shop starting preset | H52: Measure substrate and jig. | J52: =IF(OR(E52<=0,F52<=0),"ERROR - NONPOSITIVE",IF(OR(E52<'01-Process Controls'!$G$7,F52<'01-Process Controls'!$G$7),"ERROR - BELOW MIN",IF(OR(AND(E52<='01-Process Controls'!$D$7-2*'01-Process Controls'!$H$7,F52<='01-Process Controls'!$E$7-2*'01-Process Controls'!$H$7),AND(E52<='01-Process Controls'!$E$7-2*'01-Process Controls'!$H$7,F52<='01-Process Controls'!$D$7-2*'01-Process Controls'!$H$7)),"VALID - SAFE",IF(OR(AND(E52<='01-Process Controls'!$D$7,F52<='01-Process Controls'!$E$7),AND(E52<='01-Process Controls'!$E$7,F52<='01-Process Controls'!$D$7)),"VALID - NOMINAL EDGE","ERROR - EXCEEDS BED")))) -> VALID - SAFE | K52: YES
A53: UV-12 | B53: UV | C53: Rigid panel | D53: Square | E53: 120 | F53: 120 | G53: Shop starting preset | H53: Measure substrate and jig. | J53: =IF(OR(E53<=0,F53<=0),"ERROR - NONPOSITIVE",IF(OR(E53<'01-Process Controls'!$G$7,F53<'01-Process Controls'!$G$7),"ERROR - BELOW MIN",IF(OR(AND(E53<='01-Process Controls'!$D$7-2*'01-Process Controls'!$H$7,F53<='01-Process Controls'!$E$7-2*'01-Process Controls'!$H$7),AND(E53<='01-Process Controls'!$E$7-2*'01-Process Controls'!$H$7,F53<='01-Process Controls'!$D$7-2*'01-Process Controls'!$H$7)),"VALID - SAFE",IF(OR(AND(E53<='01-Process Controls'!$D$7,F53<='01-Process Controls'!$E$7),AND(E53<='01-Process Controls'!$E$7,F53<='01-Process Controls'!$D$7)),"VALID - NOMINAL EDGE","ERROR - EXCEEDS BED")))) -> VALID - SAFE | K53: YES
A54: UV-13 | B54: UV | C54: Small item | D54: Square | E54: 50 | F54: 50 | G54: Shop starting preset | H54: Check fixture and minimum detail. | J54: =IF(OR(E54<=0,F54<=0),"ERROR - NONPOSITIVE",IF(OR(E54<'01-Process Controls'!$G$7,F54<'01-Process Controls'!$G$7),"ERROR - BELOW MIN",IF(OR(AND(E54<='01-Process Controls'!$D$7-2*'01-Process Controls'!$H$7,F54<='01-Process Controls'!$E$7-2*'01-Process Controls'!$H$7),AND(E54<='01-Process Controls'!$E$7-2*'01-Process Controls'!$H$7,F54<='01-Process Controls'!$D$7-2*'01-Process Controls'!$H$7)),"VALID - SAFE",IF(OR(AND(E54<='01-Process Controls'!$D$7,F54<='01-Process Controls'!$E$7),AND(E54<='01-Process Controls'!$E$7,F54<='01-Process Controls'!$D$7)),"VALID - NOMINAL EDGE","ERROR - EXCEEDS BED")))) -> VALID - SAFE | K54: YES
A55: UV-14 | B55: UV | C55: Photo block | D55: Landscape | E55: 100 | F55: 75 | G55: Common blank starting preset | H55: Verify exact blank dimensions and printable face. | J55: =IF(OR(E55<=0,F55<=0),"ERROR - NONPOSITIVE",IF(OR(E55<'01-Process Controls'!$G$7,F55<'01-Process Controls'!$G$7),"ERROR - BELOW MIN",IF(OR(AND(E55<='01-Process Controls'!$D$7-2*'01-Process Controls'!$H$7,F55<='01-Process Controls'!$E$7-2*'01-Process Controls'!$H$7),AND(E55<='01-Process Controls'!$E$7-2*'01-Process Controls'!$H$7,F55<='01-Process Controls'!$D$7-2*'01-Process Controls'!$H$7)),"VALID - SAFE",IF(OR(AND(E55<='01-Process Controls'!$D$7,F55<='01-Process Controls'!$E$7),AND(E55<='01-Process Controls'!$E$7,F55<='01-Process Controls'!$D$7)),"VALID - NOMINAL EDGE","ERROR - EXCEEDS BED")))) -> VALID - SAFE | K55: YES
A56: UV-15 | B56: UV | C56: Photo block | D56: Landscape | E56: 150 | F56: 100 | G56: Common blank starting preset | H56: Verify exact blank dimensions and printable face. | J56: =IF(OR(E56<=0,F56<=0),"ERROR - NONPOSITIVE",IF(OR(E56<'01-Process Controls'!$G$7,F56<'01-Process Controls'!$G$7),"ERROR - BELOW MIN",IF(OR(AND(E56<='01-Process Controls'!$D$7-2*'01-Process Controls'!$H$7,F56<='01-Process Controls'!$E$7-2*'01-Process Controls'!$H$7),AND(E56<='01-Process Controls'!$E$7-2*'01-Process Controls'!$H$7,F56<='01-Process Controls'!$D$7-2*'01-Process Controls'!$H$7)),"VALID - SAFE",IF(OR(AND(E56<='01-Process Controls'!$D$7,F56<='01-Process Controls'!$E$7),AND(E56<='01-Process Controls'!$E$7,F56<='01-Process Controls'!$D$7)),"VALID - NOMINAL EDGE","ERROR - EXCEEDS BED")))) -> VALID - SAFE | K56: YES
A57: UV-16 | B57: UV | C57: Photo block | D57: Landscape | E57: 200 | F57: 150 | G57: Common blank starting preset | H57: Verify exact blank dimensions and printable face. | J57: =IF(OR(E57<=0,F57<=0),"ERROR - NONPOSITIVE",IF(OR(E57<'01-Process Controls'!$G$7,F57<'01-Process Controls'!$G$7),"ERROR - BELOW MIN",IF(OR(AND(E57<='01-Process Controls'!$D$7-2*'01-Process Controls'!$H$7,F57<='01-Process Controls'!$E$7-2*'01-Process Controls'!$H$7),AND(E57<='01-Process Controls'!$E$7-2*'01-Process Controls'!$H$7,F57<='01-Process Controls'!$D$7-2*'01-Process Controls'!$H$7)),"VALID - SAFE",IF(OR(AND(E57<='01-Process Controls'!$D$7,F57<='01-Process Controls'!$E$7),AND(E57<='01-Process Controls'!$E$7,F57<='01-Process Controls'!$D$7)),"VALID - NOMINAL EDGE","ERROR - EXCEEDS BED")))) -> VALID - SAFE | K57: YES
A58: UV-17 | B58: UV | C58: Photo block / panel | D58: Landscape | E58: 300 | F58: 200 | G58: Common blank starting preset | H58: Verify exact blank dimensions and printable face. | J58: =IF(OR(E58<=0,F58<=0),"ERROR - NONPOSITIVE",IF(OR(E58<'01-Process Controls'!$G$7,F58<'01-Process Controls'!$G$7),"ERROR - BELOW MIN",IF(OR(AND(E58<='01-Process Controls'!$D$7-2*'01-Process Controls'!$H$7,F58<='01-Process Controls'!$E$7-2*'01-Process Controls'!$H$7),AND(E58<='01-Process Controls'!$E$7-2*'01-Process Controls'!$H$7,F58<='01-Process Controls'!$D$7-2*'01-Process Controls'!$H$7)),"VALID - SAFE",IF(OR(AND(E58<='01-Process Controls'!$D$7,F58<='01-Process Controls'!$E$7),AND(E58<='01-Process Controls'!$E$7,F58<='01-Process Controls'!$D$7)),"VALID - NOMINAL EDGE","ERROR - EXCEEDS BED")))) -> VALID - SAFE | K58: YES
A59: UV-18 | B59: UV | C59: Acrylic sign | D59: Landscape | E59: 400 | F59: 300 | G59: Shop starting preset | H59: Allow finishing and mounting clearance. | J59: =IF(OR(E59<=0,F59<=0),"ERROR - NONPOSITIVE",IF(OR(E59<'01-Process Controls'!$G$7,F59<'01-Process Controls'!$G$7),"ERROR - BELOW MIN",IF(OR(AND(E59<='01-Process Controls'!$D$7-2*'01-Process Controls'!$H$7,F59<='01-Process Controls'!$E$7-2*'01-Process Controls'!$H$7),AND(E59<='01-Process Controls'!$E$7-2*'01-Process Controls'!$H$7,F59<='01-Process Controls'!$D$7-2*'01-Process Controls'!$H$7)),"VALID - SAFE",IF(OR(AND(E59<='01-Process Controls'!$D$7,F59<='01-Process Controls'!$E$7),AND(E59<='01-Process Controls'!$E$7,F59<='01-Process Controls'!$D$7)),"VALID - NOMINAL EDGE","ERROR - EXCEEDS BED")))) -> VALID - SAFE | K59: YES
A60: UV-19 | B60: UV | C60: Acrylic sign | D60: Landscape | E60: 500 | F60: 300 | G60: Shop starting preset | H60: Allow finishing and mounting clearance. | J60: =IF(OR(E60<=0,F60<=0),"ERROR - NONPOSITIVE",IF(OR(E60<'01-Process Controls'!$G$7,F60<'01-Process Controls'!$G$7),"ERROR - BELOW MIN",IF(OR(AND(E60<='01-Process Controls'!$D$7-2*'01-Process Controls'!$H$7,F60<='01-Process Controls'!$E$7-2*'01-Process Controls'!$H$7),AND(E60<='01-Process Controls'!$E$7-2*'01-Process Controls'!$H$7,F60<='01-Process Controls'!$D$7-2*'01-Process Controls'!$H$7)),"VALID - SAFE",IF(OR(AND(E60<='01-Process Controls'!$D$7,F60<='01-Process Controls'!$E$7),AND(E60<='01-Process Controls'!$E$7,F60<='01-Process Controls'!$D$7)),"VALID - NOMINAL EDGE","ERROR - EXCEEDS BED")))) -> VALID - SAFE | K60: YES
... A76: UV-35 | B76: UV | C76: Wide panel | D76: Landscape | E76: 600 | F76: 300 | G76: Shop starting preset | H76: Nominal full width; likely edge-margin caution. | J76: =IF(OR(E76<=0,F76<=0),"ERROR - NONPOSITIVE",IF(OR(E76<'01-Process Controls'!$G$7,F76<'01-Process Controls'!$G$7),"ERROR - BELOW MIN",IF(OR(AND(E76<='01-Process Controls'!$D$7-2*'01-Process Controls'!$H$7,F76<='01-Process Controls'!$E$7-2*'01-Process Controls'!$H$7),AND(E76<='01-Process Controls'!$E$7-2*'01-Process Controls'!$H$7,F76<='01-Process Controls'!$D$7-2*'01-Process Controls'!$H$7)),"VALID - SAFE",IF(OR(AND(E76<='01-Process Controls'!$D$7,F76<='01-Process Controls'!$E$7),AND(E76<='01-Process Controls'!$E$7,F76<='01-Process Controls'!$D$7)),"VALID - NOMINAL EDGE","ERROR - EXCEEDS BED")))) -> VALID - SAFE | K76: YES
A77: LCCO2 | B77: LCCO2 | C77: Nominal full bed | D77: Flatbed | E77: =ROUNDDOWN('01-Process Controls'!$D$8,0) -> 1300 | F77: =ROUNDDOWN('01-Process Controls'!$E$8,0) -> 900 | G77: Machine-derived | H77: Nominal working bed. | I77: https://www.troteclaser.com/en-tt/laser-machines/affordable-laser-cutter-r-series | J77: =IF(OR(E77<=0,F77<=0),"ERROR - NONPOSITIVE",IF(OR(E77<>ROUNDDOWN(E77,0),F77<>ROUNDDOWN(F77,0)),"ERROR - WHOLE MM ONLY",IF(OR(E77<'01-Process Controls'!$G$8,F77<'01-Process Controls'!$G$8),"ERROR - BELOW MIN",IF(OR(AND(E77<='01-Process Controls'!$D$8-2*'01-Process Controls'!$H$8,F77<='01-Process Controls'!$E$8-2*'01-Process Controls'!$H$8),AND(E77<='01-Process Controls'!$E$8-2*'01-Process Controls'!$H$8,F77<='01-Process Controls'!$D$8-2*'01-Process Controls'!$H$8)),"VALID - SAFE",IF(OR(AND(E77<='01-Process Controls'!$D$8,F77<='01-Process Controls'!$E$8),AND(E77<='01-Process Controls'!$E$8,F77<='01-Process Controls'!$D$8)),"VALID - NOMINAL EDGE","ERROR - EXCEEDS BED"))))) -> VALID - NOMINAL EDGE | K77: YES
