Workbook
Name Apparel: #REF!
Name Apparel: #REF!
Name Brand: #REF!
Name Brand: #REF!
Name Colour: #REF!
Name Colour: #REF!
Name Department: #REF!
Name Department: #REF!
Name DesignPrintColour: #REF!
Name DesignPrintColour: #REF!
Name DesignType: #REF!
Name DesignType: #REF!
Name Dimension: #REF!
Name Dimension: #REF!
Name ExactFabric: #REF!
Name ExactFabric: #REF!
Name Fabric: #REF!
Name Fabric: #REF!
Name Fit: #REF!
Name Fit: #REF!
Name Gender: #REF!
Name Gender: #REF!
Name GenderSequence: #REF!
Name GenderSequence: #REF!
Name IsExempt: #REF!
Name IsExempt: #REF!
Name ListingVariation: #REF!
Name ListingVariation: #REF!
Name Machine: #REF!
Name Machine: #REF!
Name Neck: #REF!
Name Neck: #REF!
Name Orientation: #REF!
Name Orientation: #REF!
Name PackagingBox: #REF!
Name PackagingBox: #REF!
Name PrintingStatus: #REF!
Name PrintingStatus: #REF!
Name PrintingType: #REF!
Name PrintingType: #REF!
Name PrintPosition: #REF!
Name PrintPosition: #REF!
Name PrintPositionCount: #REF!
Name PrintPositionCount: #REF!
Name PrintSize: #REF!
Name PrintSize: #REF!
Name ProductCode: #REF!
Name ProductCode: #REF!
Name ProductType: #REF!
Name ProductType: #REF!
Name Shape: #REF!
Name Shape: #REF!
Name ShippingCarrier: #REF!
Name ShippingCarrier: #REF!
Name ShippingPackage: #REF!
Name ShippingPackage: #REF!
Name ShippingService: #REF!
Name ShippingService: #REF!
Name Size: #REF!
Name Size: #REF!

Sheet 00-Content
A1: serial | B1: tilke
A2: 1
A3: 2
A4: 3
A5: 4
A6: 5
A7: 6
A8: 7
A9: 8
A10: 9
A11: 10
A12: 11
A13: 12

Sheet Guide
A1: Code | B1: Product Tile | C1: Code | D1: Average Product Weight (g) | E1: Average Packaging Weight (g) | F1: Total Shipping Weight (g) | G1: Typical UK Shipping Fit | H1: Weight Source | T1: 1 | U1: 2 | V1: 3 | W1: 4 | X1: 5 | Y1: 6 | Z1: 7 | AA1: 8 | AB1: 9 | AC1: 10 | AD1: 12 | AE1: 13 | AF1: 14 | AG1: 15 | AH1: 16 | AI1: 17 | AJ1: 18 | AK1: 19 | AL1: 20 | AM1: 21 | AN1: 22 | AO1: 23 | BX1: A0 | BY1: 841 | BZ1: 1189 | CA1: 84.1 | CB1: 118.9 | CC1: 33.1 | CD1: 46.8
A2: PT1 | B2: 1. POD APPAREL (CLOTHING) | C2: PT1 | P2: Front | Q2: Top | T2: F1 | U2: Front | W2: Left | X2: Chest | Y2: Top | Z2: Bottom | AB2: {=_xlfn.TEXTJOIN(" ",TRUE,IF(TRIM(U2:AA2)="","",TRIM(U2:AA2)))} -> Front Left Chest Top Bottom | AC2: {=_xlfn.TEXTJOIN("-",TRUE,IF(TRIM(U2:AA2)="","",TRIM(U2:AA2)))} -> Front-Left-Chest-Top-Bottom | AD2: {=_xlfn.TEXTJOIN("",TRUE,LEFT(U2:AA2,1))} -> FLCTB | AE2: {=_xlfn.TEXTJOIN("/",TRUE,LEFT(U2:AA2,1))&"/"} -> F/L/C/T/B/ | AF2: {=_xlfn.TEXTJOIN("-",TRUE,LEFT(U2:AA2,1))&"-"} -> F-L-C-T-B- | BX2: A1 | BY2: 594 | BZ2: 841 | CA2: 59.4 | CB2: 84.1 | CC2: 23.4 | CD2: 33.1
A3: PT2 | B3: T-SHIRTS | C3: PT2 | P3: Back | Q3: Bottom | T3: F2 | U3: Front | W3: Right | X3: Chest | Y3: Top | Z3: Bottom | AB3: {=_xlfn.TEXTJOIN(" ",TRUE,IF(TRIM(U3:AA3)="","",TRIM(U3:AA3)))} -> Front Right Chest Top Bottom | AC3: {=_xlfn.TEXTJOIN("-",TRUE,IF(TRIM(U3:AA3)="","",TRIM(U3:AA3)))} -> Front-Right-Chest-Top-Bottom | AD3: {=_xlfn.TEXTJOIN("",TRUE,LEFT(U3:AA3,1))} -> FRCTB | AE3: {=_xlfn.TEXTJOIN("/",TRUE,LEFT(U3:AA3,1))&"/"} -> F/R/C/T/B/ | AF3: {=_xlfn.TEXTJOIN("-",TRUE,LEFT(U3:AA3,1))&"-"} -> F-R-C-T-B- | BX3: A2 | BY3: 420 | BZ3: 594 | CA3: 42 | CB3: 59.4 | CC3: 16.5 | CD3: 23.4
A4: PT3 | B4: Unisex Basic T-shirt | C4: PT3 | D4: 200 | E4: 60 | F4: 260 | G4: Large Letter / Small Parcel | H4: Estimated | P4: Left | Q4: Left | T4: F3 | U4: Front | W4: Middle | X4: Chest | Y4: Top | Z4: Bottom | AB4: {=_xlfn.TEXTJOIN(" ",TRUE,IF(TRIM(U4:AA4)="","",TRIM(U4:AA4)))} -> Front Middle Chest Top Bottom | AC4: {=_xlfn.TEXTJOIN("-",TRUE,IF(TRIM(U4:AA4)="","",TRIM(U4:AA4)))} -> Front-Middle-Chest-Top-Bottom | AD4: {=_xlfn.TEXTJOIN("",TRUE,LEFT(U4:AA4,1))} -> FMCTB | AE4: {=_xlfn.TEXTJOIN("/",TRUE,LEFT(U4:AA4,1))&"/"} -> F/M/C/T/B/ | AF4: {=_xlfn.TEXTJOIN("-",TRUE,LEFT(U4:AA4,1))&"-"} -> F-M-C-T-B- | BX4: A3 | BY4: 297 | BZ4: 420 | CA4: 29.7 | CB4: 42 | CC4: 11.7 | CD4: 16.5
A5: PT4 | B5: Premium T-shirt | C5: PT4 | D5: 240 | E5: 60 | F5: 300 | G5: Royal Mail Small Parcel | H5: Estimated | P5: Right | Q5: Right | T5: F4 | U5: Front | W5: Top | X5: Centre | AB5: {=_xlfn.TEXTJOIN(" ",TRUE,IF(TRIM(U5:AA5)="","",TRIM(U5:AA5)))} -> Front Top Centre | AC5: {=_xlfn.TEXTJOIN("-",TRUE,IF(TRIM(U5:AA5)="","",TRIM(U5:AA5)))} -> Front-Top-Centre | AD5: {=_xlfn.TEXTJOIN("",TRUE,LEFT(U5:AA5,1))} -> FTC | AE5: {=_xlfn.TEXTJOIN("/",TRUE,LEFT(U5:AA5,1))&"/"} -> F/T/C/ | AF5: {=_xlfn.TEXTJOIN("-",TRUE,LEFT(U5:AA5,1))&"-"} -> F-T-C- | AG5: A4 | AH5: A3 | AI5: A2/80 | BX5: A4 | BY5: 210 | BZ5: 297 | CA5: 21 | CB5: 29.7 | CC5: 8.3 | CD5: 11.7
A6: PT5 | B6: Heavy Cotton Tee | C6: PT5 | D6: 240 | E6: 60 | F6: 300 | G6: Royal Mail Small Parcel | H6: Estimated | P6: Top | Q6: Centre | T6: F5 | U6: Front | W6: Left | X6: Middle | Y6: Top | Z6: Bottom | AB6: {=_xlfn.TEXTJOIN(" ",TRUE,IF(TRIM(U6:AA6)="","",TRIM(U6:AA6)))} -> Front Left Middle Top Bottom | AC6: {=_xlfn.TEXTJOIN("-",TRUE,IF(TRIM(U6:AA6)="","",TRIM(U6:AA6)))} -> Front-Left-Middle-Top-Bottom | AD6: {=_xlfn.TEXTJOIN("",TRUE,LEFT(U6:AA6,1))} -> FLMTB | AE6: {=_xlfn.TEXTJOIN("/",TRUE,LEFT(U6:AA6,1))&"/"} -> F/L/M/T/B/ | AF6: {=_xlfn.TEXTJOIN("-",TRUE,LEFT(U6:AA6,1))&"-"} -> F-L-M-T-B- | BX6: A5 | BY6: 148 | BZ6: 210 | CA6: 14.8 | CB6: 21 | CC6: 5.8 | CD6: 8.3
A7: PT6 | B7: Oversized Streetwear Tee | C7: PT6 | D7: 240 | E7: 60 | F7: 300 | G7: Royal Mail Small Parcel | H7: Estimated | P7: Bottom | Q7: Middle | T7: F6 | U7: Front | W7: Right | X7: Middle | Y7: Top | Z7: Bottom | AB7: {=_xlfn.TEXTJOIN(" ",TRUE,IF(TRIM(U7:AA7)="","",TRIM(U7:AA7)))} -> Front Right Middle Top Bottom | AC7: {=_xlfn.TEXTJOIN("-",TRUE,IF(TRIM(U7:AA7)="","",TRIM(U7:AA7)))} -> Front-Right-Middle-Top-Bottom | AD7: {=_xlfn.TEXTJOIN("",TRUE,LEFT(U7:AA7,1))} -> FRMTB | AE7: {=_xlfn.TEXTJOIN("/",TRUE,LEFT(U7:AA7,1))&"/"} -> F/R/M/T/B/ | AF7: {=_xlfn.TEXTJOIN("-",TRUE,LEFT(U7:AA7,1))&"-"} -> F-R-M-T-B- | BX7: A6 | BY7: 105 | BZ7: 148 | CA7: 10.5 | CB7: 14.8 | CC7: 4.1 | CD7: 5.8
A8: PT7 | B8: Women’s Fitted Tee | C8: PT7 | D8: 200 | E8: 60 | F8: 260 | G8: Large Letter / Small Parcel | H8: Estimated | P8: Sleeve | Q8: Corner | T8: F7 | U8: Front | W8: Middle | X8: Centre | Y8: Top | Z8: Bottom | AB8: {=_xlfn.TEXTJOIN(" ",TRUE,IF(TRIM(U8:AA8)="","",TRIM(U8:AA8)))} -> Front Middle Centre Top Bottom | AC8: {=_xlfn.TEXTJOIN("-",TRUE,IF(TRIM(U8:AA8)="","",TRIM(U8:AA8)))} -> Front-Middle-Centre-Top-Bottom | AD8: {=_xlfn.TEXTJOIN("",TRUE,LEFT(U8:AA8,1))} -> FMCTB | AE8: {=_xlfn.TEXTJOIN("/",TRUE,LEFT(U8:AA8,1))&"/"} -> F/M/C/T/B/ | AF8: {=_xlfn.TEXTJOIN("-",TRUE,LEFT(U8:AA8,1))&"-"} -> F-M-C-T-B- | BX8: A7 | BY8: 74 | BZ8: 105 | CA8: 7.4 | CB8: 10.5 | CC8: 2.9 | CD8: 4.1
A9: PT8 | B9: Ringer Tee | C9: PT8 | D9: 200 | E9: 60 | F9: 260 | G9: Large Letter / Small Parcel | H9: Estimated | P9: Half | Q9: Chest | T9: F8 | U9: Front | W9: Left | X9: Chest | AB9: {=_xlfn.TEXTJOIN(" ",TRUE,IF(TRIM(U9:AA9)="","",TRIM(U9:AA9)))} -> Front Left Chest | AC9: {=_xlfn.TEXTJOIN("-",TRUE,IF(TRIM(U9:AA9)="","",TRIM(U9:AA9)))} -> Front-Left-Chest | AD9: {=_xlfn.TEXTJOIN("",TRUE,LEFT(U9:AA9,1))} -> FLC | AE9: {=_xlfn.TEXTJOIN("/",TRUE,LEFT(U9:AA9,1))&"/"} -> F/L/C/ | AF9: {=_xlfn.TEXTJOIN("-",TRUE,LEFT(U9:AA9,1))&"-"} -> F-L-C- | AG9: A9 | AH9: A8 | AI9: A7 | BX9: A8 | BY9: 52 | BZ9: 74 | CA9: 5.2 | CB9: 7.4 | CC9: 2 | CD9: 2.9
A10: PT9 | B10: Long Sleeve T-shirt | C10: PT9 | D10: 240 | E10: 60 | F10: 300 | G10: Royal Mail Small Parcel | H10: Estimated | P10: Short | T10: F9 | U10: Front | W10: Right | X10: Chest | AB10: {=_xlfn.TEXTJOIN(" ",TRUE,IF(TRIM(U10:AA10)="","",TRIM(U10:AA10)))} -> Front Right Chest | AC10: {=_xlfn.TEXTJOIN("-",TRUE,IF(TRIM(U10:AA10)="","",TRIM(U10:AA10)))} -> Front-Right-Chest | AD10: {=_xlfn.TEXTJOIN("",TRUE,LEFT(U10:AA10,1))} -> FRC | AE10: {=_xlfn.TEXTJOIN("/",TRUE,LEFT(U10:AA10,1))&"/"} -> F/R/C/ | AF10: {=_xlfn.TEXTJOIN("-",TRUE,LEFT(U10:AA10,1))&"-"} -> F-R-C- | BX10: A9 | BY10: 37 | BZ10: 52 | CA10: 3.7 | CB10: 5.2 | CC10: 1.5 | CD10: 2
A11: PT10 | B11: Pocket T-shirt | C11: PT10 | D11: 200 | E11: 60 | F11: 260 | G11: Large Letter / Small Parcel | H11: Estimated | P11: Full | T11: F10 | U11: Front | W11: Bottom | X11: Left | Y11: Corner | AB11: {=_xlfn.TEXTJOIN(" ",TRUE,IF(TRIM(U11:AA11)="","",TRIM(U11:AA11)))} -> Front Bottom Left Corner | AC11: {=_xlfn.TEXTJOIN("-",TRUE,IF(TRIM(U11:AA11)="","",TRIM(U11:AA11)))} -> Front-Bottom-Left-Corner | AD11: {=_xlfn.TEXTJOIN("",TRUE,LEFT(U11:AA11,1))} -> FBLC | AE11: {=_xlfn.TEXTJOIN("/",TRUE,LEFT(U11:AA11,1))&"/"} -> F/B/L/C/ | AF11: {=_xlfn.TEXTJOIN("-",TRUE,LEFT(U11:AA11,1))&"-"} -> F-B-L-C- | BX11: A10 | BY11: 26 | BZ11: 37 | CA11: 2.6 | CB11: 3.7 | CC11: 1 | CD11: 1.5
A12: PT11 | B12: V-neck Tee | C12: PT11 | D12: 200 | E12: 60 | F12: 260 | G12: Large Letter / Small Parcel | H12: Estimated | P12: inside Neck | T12: F11 | U12: Front | W12: Bottom | X12: Right | Y12: Corner | AB12: {=_xlfn.TEXTJOIN(" ",TRUE,IF(TRIM(U12:AA12)="","",TRIM(U12:AA12)))} -> Front Bottom Right Corner | AC12: {=_xlfn.TEXTJOIN("-",TRUE,IF(TRIM(U12:AA12)="","",TRIM(U12:AA12)))} -> Front-Bottom-Right-Corner | AD12: {=_xlfn.TEXTJOIN("",TRUE,LEFT(U12:AA12,1))} -> FBRC | AE12: {=_xlfn.TEXTJOIN("/",TRUE,LEFT(U12:AA12,1))&"/"} -> F/B/R/C/ | AF12: {=_xlfn.TEXTJOIN("-",TRUE,LEFT(U12:AA12,1))&"-"} -> F-B-R-C- | BX12: A11 | BY12: 18 | BZ12: 26 | CA12: 1.8 | CB12: 2.6 | CC12: 0.7 | CD12: 1
A13: PT12 | B13: Kids Custom T-shirt | C13: PT12 | D13: 140 | E13: 50 | F13: 190 | G13: Large Letter / Small Parcel | H13: Estimated | P13: outside Neck | T13: F12 | U13: Front | W13: Top | X13: Left | Y13: Corner | Z13: Top | AA13: Left | AB13: {=_xlfn.TEXTJOIN(" ",TRUE,IF(TRIM(U13:AA13)="","",TRIM(U13:AA13)))} -> Front Top Left Corner Top Left | AC13: {=_xlfn.TEXTJOIN("-",TRUE,IF(TRIM(U13:AA13)="","",TRIM(U13:AA13)))} -> Front-Top-Left-Corner-Top-Left | AD13: {=_xlfn.TEXTJOIN("",TRUE,LEFT(U13:AA13,1))} -> FTLCTL | AE13: {=_xlfn.TEXTJOIN("/",TRUE,LEFT(U13:AA13,1))&"/"} -> F/T/L/C/T/L/ | AF13: {=_xlfn.TEXTJOIN("-",TRUE,LEFT(U13:AA13,1))&"-"} -> F-T-L-C-T-L- | BX13: A12 | BY13: 13 | BZ13: 18 | CA13: 1.3 | CB13: 1.8 | CC13: 0.5 | CD13: 0.7
A14: PT13 | B14: SWEATSHIRTS & HOODIES | C14: PT13 | T14: F13 | U14: Front | W14: Top | X14: Right | Y14: Corner | Z14: Top | AA14: Right | AB14: {=_xlfn.TEXTJOIN(" ",TRUE,IF(TRIM(U14:AA14)="","",TRIM(U14:AA14)))} -> Front Top Right Corner Top Right | AC14: {=_xlfn.TEXTJOIN("-",TRUE,IF(TRIM(U14:AA14)="","",TRIM(U14:AA14)))} -> Front-Top-Right-Corner-Top-Right | AD14: {=_xlfn.TEXTJOIN("",TRUE,LEFT(U14:AA14,1))} -> FTRCTR | AE14: {=_xlfn.TEXTJOIN("/",TRUE,LEFT(U14:AA14,1))&"/"} -> F/T/R/C/T/R/ | AF14: {=_xlfn.TEXTJOIN("-",TRUE,LEFT(U14:AA14,1))&"-"} -> F-T-R-C-T-R- | BX14: A13 | BY14: 9 | BZ14: 13 | CA14: 0.9 | CB14: 1.3 | CC14: 0.4 | CD14: 0.5
A15: PT14 | B15: Classic Pullover Hoodie | C15: PT14 | D15: 750 | E15: 80 | F15: 830 | G15: Royal Mail Small Parcel | H15: Estimated | T15: F14 | U15: Front | W15: Top | X15: Left | Y15: Corner | AB15: {=_xlfn.TEXTJOIN(" ",TRUE,IF(TRIM(U15:AA15)="","",TRIM(U15:AA15)))} -> Front Top Left Corner | AC15: {=_xlfn.TEXTJOIN("-",TRUE,IF(TRIM(U15:AA15)="","",TRIM(U15:AA15)))} -> Front-Top-Left-Corner | AD15: {=_xlfn.TEXTJOIN("",TRUE,LEFT(U15:AA15,1))} -> FTLC | AE15: {=_xlfn.TEXTJOIN("/",TRUE,LEFT(U15:AA15,1))&"/"} -> F/T/L/C/ | AF15: {=_xlfn.TEXTJOIN("-",TRUE,LEFT(U15:AA15,1))&"-"} -> F-T-L-C- | BX15: 2A0 | BY15: 1189 | BZ15: 1682 | CA15: 118.9 | CB15: 168.2 | CC15: 46.8 | CD15: 66.2
A16: PT15 | B16: Zip Hoodie | C16: PT15 | D16: 800 | E16: 90 | F16: 890 | G16: Royal Mail Small Parcel | H16: Estimated | T16: F15 | U16: Front | W16: Top | X16: Right | Y16: Corner | AB16: {=_xlfn.TEXTJOIN(" ",TRUE,IF(TRIM(U16:AA16)="","",TRIM(U16:AA16)))} -> Front Top Right Corner | AC16: {=_xlfn.TEXTJOIN("-",TRUE,IF(TRIM(U16:AA16)="","",TRIM(U16:AA16)))} -> Front-Top-Right-Corner | AD16: {=_xlfn.TEXTJOIN("",TRUE,LEFT(U16:AA16,1))} -> FTRC | AE16: {=_xlfn.TEXTJOIN("/",TRUE,LEFT(U16:AA16,1))&"/"} -> F/T/R/C/ | AF16: {=_xlfn.TEXTJOIN("-",TRUE,LEFT(U16:AA16,1))&"-"} -> F-T-R-C- | BX16: 4A0 | BY16: 1682 | BZ16: 2378 | CA16: 168.2 | CB16: 237.8 | CC16: 66.2 | CD16: 93.6
A17: PT16 | B17: Heavy Blend Hoodie | C17: PT16 | D17: 750 | E17: 80 | F17: 830 | G17: Royal Mail Small Parcel | H17: Estimated | T17: F16 | U17: Front | W17: Top | X17: Left | Y17: Bottom | Z17: Right | AA17: Corner | AB17: {=_xlfn.TEXTJOIN(" ",TRUE,IF(TRIM(U17:AA17)="","",TRIM(U17:AA17)))} -> Front Top Left Bottom Right Corner | AC17: {=_xlfn.TEXTJOIN("-",TRUE,IF(TRIM(U17:AA17)="","",TRIM(U17:AA17)))} -> Front-Top-Left-Bottom-Right-Corner | AD17: {=_xlfn.TEXTJOIN("",TRUE,LEFT(U17:AA17,1))} -> FTLBRC | AE17: {=_xlfn.TEXTJOIN("/",TRUE,LEFT(U17:AA17,1))&"/"} -> F/T/L/B/R/C/ | AF17: {=_xlfn.TEXTJOIN("-",TRUE,LEFT(U17:AA17,1))&"-"} -> F-T-L-B-R-C- | BX17: A0+ | BY17: 914 | BZ17: 1292 | CA17: 91.4 | CB17: 129.2 | CC17: 36 | CD17: 50.9
A18: PT17 | B18: Crewneck Sweatshirt | C18: PT17 | D18: 520 | E18: 80 | F18: 600 | G18: Royal Mail Small Parcel | H18: Estimated | T18: F17 | U18: Front | W18: Top | X18: Right | Y18: Corner | Z18: Left | AA18: Corner | AB18: {=_xlfn.TEXTJOIN(" ",TRUE,IF(TRIM(U18:AA18)="","",TRIM(U18:AA18)))} -> Front Top Right Corner Left Corner | AC18: {=_xlfn.TEXTJOIN("-",TRUE,IF(TRIM(U18:AA18)="","",TRIM(U18:AA18)))} -> Front-Top-Right-Corner-Left-Corner | AD18: {=_xlfn.TEXTJOIN("",TRUE,LEFT(U18:AA18,1))} -> FTRCLC | AE18: {=_xlfn.TEXTJOIN("/",TRUE,LEFT(U18:AA18,1))&"/"} -> F/T/R/C/L/C/ | AF18: {=_xlfn.TEXTJOIN("-",TRUE,LEFT(U18:AA18,1))&"-"} -> F-T-R-C-L-C- | BX18: A1+ | BY18: 609 | BZ18: 914 | CA18: 60.9 | CB18: 91.4 | CC18: 24 | CD18: 36
A19: PT18 | B19: Oversized Hoodie | C19: PT18 | D19: 750 | E19: 80 | F19: 830 | G19: Royal Mail Small Parcel | H19: Estimated | T19: F18 | U19: Front | W19: Bottom | X19: Left | Y19: Corner | Z19: Top | AA19: Left | AB19: {=_xlfn.TEXTJOIN(" ",TRUE,IF(TRIM(U19:AA19)="","",TRIM(U19:AA19)))} -> Front Bottom Left Corner Top Left | AC19: {=_xlfn.TEXTJOIN("-",TRUE,IF(TRIM(U19:AA19)="","",TRIM(U19:AA19)))} -> Front-Bottom-Left-Corner-Top-Left | AD19: {=_xlfn.TEXTJOIN("",TRUE,LEFT(U19:AA19,1))} -> FBLCTL | AE19: {=_xlfn.TEXTJOIN("/",TRUE,LEFT(U19:AA19,1))&"/"} -> F/B/L/C/T/L/ | AF19: {=_xlfn.TEXTJOIN("-",TRUE,LEFT(U19:AA19,1))&"-"} -> F-B-L-C-T-L- | BX19: A3+ | BY19: 329 | BZ19: 483 | CA19: 32.9 | CB19: 48.3 | CC19: 13 | CD19: 19
A20: PT19 | B20: College Hoodie | C20: PT19 | D20: 750 | E20: 80 | F20: 830 | G20: Royal Mail Small Parcel | H20: Estimated | T20: F19 | U20: Front | W20: Bottom | X20: Right | Y20: Corner | Z20: Top | AA20: Left | AB20: {=_xlfn.TEXTJOIN(" ",TRUE,IF(TRIM(U20:AA20)="","",TRIM(U20:AA20)))} -> Front Bottom Right Corner Top Left | AC20: {=_xlfn.TEXTJOIN("-",TRUE,IF(TRIM(U20:AA20)="","",TRIM(U20:AA20)))} -> Front-Bottom-Right-Corner-Top-Left | AD20: {=_xlfn.TEXTJOIN("",TRUE,LEFT(U20:AA20,1))} -> FBRCTL | AE20: {=_xlfn.TEXTJOIN("/",TRUE,LEFT(U20:AA20,1))&"/"} -> F/B/R/C/T/L/ | AF20: {=_xlfn.TEXTJOIN("-",TRUE,LEFT(U20:AA20,1))&"-"} -> F-B-R-C-T-L-
A21: PT20 | B21: Crop Hoodie | C21: PT20 | D21: 550 | E21: 80 | F21: 630 | G21: Royal Mail Small Parcel | H21: Estimated | T21: F20 | U21: Front | W21: Bottom | X21: Left | Y21: Corner | Z21: Top | AA21: Right | AB21: {=_xlfn.TEXTJOIN(" ",TRUE,IF(TRIM(U21:AA21)="","",TRIM(U21:AA21)))} -> Front Bottom Left Corner Top Right | AC21: {=_xlfn.TEXTJOIN("-",TRUE,IF(TRIM(U21:AA21)="","",TRIM(U21:AA21)))} -> Front-Bottom-Left-Corner-Top-Right | AD21: {=_xlfn.TEXTJOIN("",TRUE,LEFT(U21:AA21,1))} -> FBLCTR | AE21: {=_xlfn.TEXTJOIN("/",TRUE,LEFT(U21:AA21,1))&"/"} -> F/B/L/C/T/R/ | AF21: {=_xlfn.TEXTJOIN("-",TRUE,LEFT(U21:AA21,1))&"-"} -> F-B-L-C-T-R-
A22: PT21 | B22: Kids Hoodie | C22: PT21 | D22: 500 | E22: 80 | F22: 580 | G22: Royal Mail Small Parcel | H22: Estimated | T22: F21 | U22: Front | W22: Bottom | X22: Right | Y22: Corner | Z22: Top | AA22: Right | AB22: {=_xlfn.TEXTJOIN(" ",TRUE,IF(TRIM(U22:AA22)="","",TRIM(U22:AA22)))} -> Front Bottom Right Corner Top Right | AC22: {=_xlfn.TEXTJOIN("-",TRUE,IF(TRIM(U22:AA22)="","",TRIM(U22:AA22)))} -> Front-Bottom-Right-Corner-Top-Right | AD22: {=_xlfn.TEXTJOIN("",TRUE,LEFT(U22:AA22,1))} -> FBRCTR | AE22: {=_xlfn.TEXTJOIN("/",TRUE,LEFT(U22:AA22,1))&"/"} -> F/B/R/C/T/R/ | AF22: {=_xlfn.TEXTJOIN("-",TRUE,LEFT(U22:AA22,1))&"-"} -> F-B-R-C-T-R-
A23: PT22 | B23: TANK TopS | C23: PT22 | T23: F22 | U23: Front | W23: Left | X23: Middle | Z23: Top | AA23: Left | AB23: {=_xlfn.TEXTJOIN(" ",TRUE,IF(TRIM(U23:AA23)="","",TRIM(U23:AA23)))} -> Front Left Middle Top Left | AC23: {=_xlfn.TEXTJOIN("-",TRUE,IF(TRIM(U23:AA23)="","",TRIM(U23:AA23)))} -> Front-Left-Middle-Top-Left | AD23: {=_xlfn.TEXTJOIN("",TRUE,LEFT(U23:AA23,1))} -> FLMTL | AE23: {=_xlfn.TEXTJOIN("/",TRUE,LEFT(U23:AA23,1))&"/"} -> F/L/M/T/L/ | AF23: {=_xlfn.TEXTJOIN("-",TRUE,LEFT(U23:AA23,1))&"-"} -> F-L-M-T-L-
A24: PT23 | B24: Unisex Tank | C24: PT23 | D24: 180 | E24: 60 | F24: 240 | G24: Large Letter / Small Parcel | H24: Estimated | T24: F23 | U24: Front | W24: Right | X24: Middle | Z24: Top | AA24: Left | AB24: {=_xlfn.TEXTJOIN(" ",TRUE,IF(TRIM(U24:AA24)="","",TRIM(U24:AA24)))} -> Front Right Middle Top Left | AC24: {=_xlfn.TEXTJOIN("-",TRUE,IF(TRIM(U24:AA24)="","",TRIM(U24:AA24)))} -> Front-Right-Middle-Top-Left | AD24: {=_xlfn.TEXTJOIN("",TRUE,LEFT(U24:AA24,1))} -> FRMTL | AE24: {=_xlfn.TEXTJOIN("/",TRUE,LEFT(U24:AA24,1))&"/"} -> F/R/M/T/L/ | AF24: {=_xlfn.TEXTJOIN("-",TRUE,LEFT(U24:AA24,1))&"-"} -> F-R-M-T-L-
A25: PT24 | B25: Women’s Racerback | C25: PT24 | T25: F24 | U25: Front | W25: Middle | X25: Centre | Z25: Top | AA25: Left | AB25: {=_xlfn.TEXTJOIN(" ",TRUE,IF(TRIM(U25:AA25)="","",TRIM(U25:AA25)))} -> Front Middle Centre Top Left | AC25: {=_xlfn.TEXTJOIN("-",TRUE,IF(TRIM(U25:AA25)="","",TRIM(U25:AA25)))} -> Front-Middle-Centre-Top-Left | AD25: {=_xlfn.TEXTJOIN("",TRUE,LEFT(U25:AA25,1))} -> FMCTL | AE25: {=_xlfn.TEXTJOIN("/",TRUE,LEFT(U25:AA25,1))&"/"} -> F/M/C/T/L/ | AF25: {=_xlfn.TEXTJOIN("-",TRUE,LEFT(U25:AA25,1))&"-"} -> F-M-C-T-L-
A26: PT25 | B26: Gym Tank / Fitness Vest | C26: PT25 | D26: 180 | E26: 60 | F26: 240 | G26: Large Letter / Small Parcel | H26: Estimated | T26: F25 | U26: Front | W26: Left | X26: Middle | Z26: Top | AA26: Right | AB26: {=_xlfn.TEXTJOIN(" ",TRUE,IF(TRIM(U26:AA26)="","",TRIM(U26:AA26)))} -> Front Left Middle Top Right | AC26: {=_xlfn.TEXTJOIN("-",TRUE,IF(TRIM(U26:AA26)="","",TRIM(U26:AA26)))} -> Front-Left-Middle-Top-Right | AD26: {=_xlfn.TEXTJOIN("",TRUE,LEFT(U26:AA26,1))} -> FLMTR | AE26: {=_xlfn.TEXTJOIN("/",TRUE,LEFT(U26:AA26,1))&"/"} -> F/L/M/T/R/ | AF26: {=_xlfn.TEXTJOIN("-",TRUE,LEFT(U26:AA26,1))&"-"} -> F-L-M-T-R-
A27: PT26 | B27: Bottom S | C27: PT26 | T27: F26 | U27: Front | W27: Right | X27: Middle | Z27: Top | AA27: Right | AB27: {=_xlfn.TEXTJOIN(" ",TRUE,IF(TRIM(U27:AA27)="","",TRIM(U27:AA27)))} -> Front Right Middle Top Right | AC27: {=_xlfn.TEXTJOIN("-",TRUE,IF(TRIM(U27:AA27)="","",TRIM(U27:AA27)))} -> Front-Right-Middle-Top-Right | AD27: {=_xlfn.TEXTJOIN("",TRUE,LEFT(U27:AA27,1))} -> FRMTR | AE27: {=_xlfn.TEXTJOIN("/",TRUE,LEFT(U27:AA27,1))&"/"} -> F/R/M/T/R/ | AF27: {=_xlfn.TEXTJOIN("-",TRUE,LEFT(U27:AA27,1))&"-"} -> F-R-M-T-R-
A28: PT27 | B28: Joggers | C28: PT27 | D28: 500 | E28: 90 | F28: 590 | G28: Royal Mail Small Parcel | H28: Estimated | T28: F27 | U28: Front | W28: Middle | X28: Centre | Z28: Top | AA28: Right | AB28: {=_xlfn.TEXTJOIN(" ",TRUE,IF(TRIM(U28:AA28)="","",TRIM(U28:AA28)))} -> Front Middle Centre Top Right | AC28: {=_xlfn.TEXTJOIN("-",TRUE,IF(TRIM(U28:AA28)="","",TRIM(U28:AA28)))} -> Front-Middle-Centre-Top-Right | AD28: {=_xlfn.TEXTJOIN("",TRUE,LEFT(U28:AA28,1))} -> FMCTR | AE28: {=_xlfn.TEXTJOIN("/",TRUE,LEFT(U28:AA28,1))&"/"} -> F/M/C/T/R/ | AF28: {=_xlfn.TEXTJOIN("-",TRUE,LEFT(U28:AA28,1))&"-"} -> F-M-C-T-R-
A29: PT28 | B29: Sweatpants | C29: PT28 | D29: 500 | E29: 90 | F29: 590 | G29: Royal Mail Small Parcel | H29: Estimated | T29: F28 | U29: Front | W29: Bottom | X29: Left | Y29: Right | AB29: {=_xlfn.TEXTJOIN(" ",TRUE,IF(TRIM(U29:AA29)="","",TRIM(U29:AA29)))} -> Front Bottom Left Right | AC29: {=_xlfn.TEXTJOIN("-",TRUE,IF(TRIM(U29:AA29)="","",TRIM(U29:AA29)))} -> Front-Bottom-Left-Right | AD29: {=_xlfn.TEXTJOIN("",TRUE,LEFT(U29:AA29,1))} -> FBLR | AE29: {=_xlfn.TEXTJOIN("/",TRUE,LEFT(U29:AA29,1))&"/"} -> F/B/L/R/ | AF29: {=_xlfn.TEXTJOIN("-",TRUE,LEFT(U29:AA29,1))&"-"} -> F-B-L-R-
A30: PT29 | B30: Shorts | C30: PT29 | D30: 250 | E30: 70 | F30: 320 | G30: Royal Mail Small Parcel | H30: Estimated | T30: F29 | U30: Front | W30: Centre | X30: Left | Y30: Right | AB30: {=_xlfn.TEXTJOIN(" ",TRUE,IF(TRIM(U30:AA30)="","",TRIM(U30:AA30)))} -> Front Centre Left Right | AC30: {=_xlfn.TEXTJOIN("-",TRUE,IF(TRIM(U30:AA30)="","",TRIM(U30:AA30)))} -> Front-Centre-Left-Right | AD30: {=_xlfn.TEXTJOIN("",TRUE,LEFT(U30:AA30,1))} -> FCLR | AE30: {=_xlfn.TEXTJOIN("/",TRUE,LEFT(U30:AA30,1))&"/"} -> F/C/L/R/ | AF30: {=_xlfn.TEXTJOIN("-",TRUE,LEFT(U30:AA30,1))&"-"} -> F-C-L-R-
A31: PT30 | B31: Leggings | C31: PT30 | D31: 220 | E31: 70 | F31: 290 | G31: Royal Mail Small Parcel | H31: Estimated | T31: F30 | U31: Front | W31: Bottom | X31: Corner | Z31: Top | AA31: Bottom | AB31: {=_xlfn.TEXTJOIN(" ",TRUE,IF(TRIM(U31:AA31)="","",TRIM(U31:AA31)))} -> Front Bottom Corner Top Bottom | AC31: {=_xlfn.TEXTJOIN("-",TRUE,IF(TRIM(U31:AA31)="","",TRIM(U31:AA31)))} -> Front-Bottom-Corner-Top-Bottom | AD31: {=_xlfn.TEXTJOIN("",TRUE,LEFT(U31:AA31,1))} -> FBCTB | AE31: {=_xlfn.TEXTJOIN("/",TRUE,LEFT(U31:AA31,1))&"/"} -> F/B/C/T/B/ | AF31: {=_xlfn.TEXTJOIN("-",TRUE,LEFT(U31:AA31,1))&"-"} -> F-B-C-T-B-
A32: PT31 | B32: Cycling Shorts | C32: PT31 | D32: 250 | E32: 70 | F32: 320 | G32: Royal Mail Small Parcel | H32: Estimated | T32: F31 | U32: Front | W32: Bottom | X32: Corner | Z32: Top | AA32: Bottom | AB32: {=_xlfn.TEXTJOIN(" ",TRUE,IF(TRIM(U32:AA32)="","",TRIM(U32:AA32)))} -> Front Bottom Corner Top Bottom | AC32: {=_xlfn.TEXTJOIN("-",TRUE,IF(TRIM(U32:AA32)="","",TRIM(U32:AA32)))} -> Front-Bottom-Corner-Top-Bottom | AD32: {=_xlfn.TEXTJOIN("",TRUE,LEFT(U32:AA32,1))} -> FBCTB | AE32: {=_xlfn.TEXTJOIN("/",TRUE,LEFT(U32:AA32,1))&"/"} -> F/B/C/T/B/ | AF32: {=_xlfn.TEXTJOIN("-",TRUE,LEFT(U32:AA32,1))&"-"} -> F-B-C-T-B-
A33: PT32 | B33: ACTIVEWEAR | C33: PT32 | T33: F32 | U33: Front | W33: Bottom | X33: Middle | Z33: Top | AA33: Bottom | AB33: {=_xlfn.TEXTJOIN(" ",TRUE,IF(TRIM(U33:AA33)="","",TRIM(U33:AA33)))} -> Front Bottom Middle Top Bottom | AC33: {=_xlfn.TEXTJOIN("-",TRUE,IF(TRIM(U33:AA33)="","",TRIM(U33:AA33)))} -> Front-Bottom-Middle-Top-Bottom | AD33: {=_xlfn.TEXTJOIN("",TRUE,LEFT(U33:AA33,1))} -> FBMTB | AE33: {=_xlfn.TEXTJOIN("/",TRUE,LEFT(U33:AA33,1))&"/"} -> F/B/M/T/B/ | AF33: {=_xlfn.TEXTJOIN("-",TRUE,LEFT(U33:AA33,1))&"-"} -> F-B-M-T-B-
A34: PT33 | B34: Sports Jersey | C34: PT33 | T34: F33 | U34: Front | W34: Top | X34: Left | Y34: Corner | Z34: Top | AA34: Right | AB34: {=_xlfn.TEXTJOIN(" ",TRUE,IF(TRIM(U34:AA34)="","",TRIM(U34:AA34)))} -> Front Top Left Corner Top Right | AC34: {=_xlfn.TEXTJOIN("-",TRUE,IF(TRIM(U34:AA34)="","",TRIM(U34:AA34)))} -> Front-Top-Left-Corner-Top-Right | AD34: {=_xlfn.TEXTJOIN("",TRUE,LEFT(U34:AA34,1))} -> FTLCTR | AE34: {=_xlfn.TEXTJOIN("/",TRUE,LEFT(U34:AA34,1))&"/"} -> F/T/L/C/T/R/ | AF34: {=_xlfn.TEXTJOIN("-",TRUE,LEFT(U34:AA34,1))&"-"} -> F-T-L-C-T-R-
A35: PT34 | B35: Compression Shirt | C35: PT34 | T35: F34 | U35: Front | W35: Top | X35: Right | Y35: Corner | Z35: Top | AA35: Left | AB35: {=_xlfn.TEXTJOIN(" ",TRUE,IF(TRIM(U35:AA35)="","",TRIM(U35:AA35)))} -> Front Top Right Corner Top Left | AC35: {=_xlfn.TEXTJOIN("-",TRUE,IF(TRIM(U35:AA35)="","",TRIM(U35:AA35)))} -> Front-Top-Right-Corner-Top-Left | AD35: {=_xlfn.TEXTJOIN("",TRUE,LEFT(U35:AA35,1))} -> FTRCTL | AE35: {=_xlfn.TEXTJOIN("/",TRUE,LEFT(U35:AA35,1))&"/"} -> F/T/R/C/T/L/ | AF35: {=_xlfn.TEXTJOIN("-",TRUE,LEFT(U35:AA35,1))&"-"} -> F-T-R-C-T-L-
A36: PT35 | B36: Men’s Gym Vest | C36: PT35 | D36: 180 | E36: 60 | F36: 240 | G36: Large Letter / Small Parcel | H36: Estimated | T36: F35 | U36: Front | W36: Top | AB36: {=_xlfn.TEXTJOIN(" ",TRUE,IF(TRIM(U36:AA36)="","",TRIM(U36:AA36)))} -> Front Top | AC36: {=_xlfn.TEXTJOIN("-",TRUE,IF(TRIM(U36:AA36)="","",TRIM(U36:AA36)))} -> Front-Top | AD36: {=_xlfn.TEXTJOIN("",TRUE,LEFT(U36:AA36,1))} -> FT | AE36: {=_xlfn.TEXTJOIN("/",TRUE,LEFT(U36:AA36,1))&"/"} -> F/T/ | AF36: {=_xlfn.TEXTJOIN("-",TRUE,LEFT(U36:AA36,1))&"-"} -> F-T-
A37: PT36 | B37: Sports Leggings | C37: PT36 | D37: 220 | E37: 70 | F37: 290 | G37: Royal Mail Small Parcel | H37: Estimated | T37: F36 | U37: Front | AB37: {=_xlfn.TEXTJOIN(" ",TRUE,IF(TRIM(U37:AA37)="","",TRIM(U37:AA37)))} -> Front | AC37: {=_xlfn.TEXTJOIN("-",TRUE,IF(TRIM(U37:AA37)="","",TRIM(U37:AA37)))} -> Front | AD37: {=_xlfn.TEXTJOIN("",TRUE,LEFT(U37:AA37,1))} -> F | AE37: {=_xlfn.TEXTJOIN("/",TRUE,LEFT(U37:AA37,1))&"/"} -> F/ | AF37: {=_xlfn.TEXTJOIN("-",TRUE,LEFT(U37:AA37,1))&"-"} -> F-
A38: PT37 | B38: BABY & KIDS APPAREL | C38: PT37 | T38: F37 | U38: Front | AB38: {=_xlfn.TEXTJOIN(" ",TRUE,IF(TRIM(U38:AA38)="","",TRIM(U38:AA38)))} -> Front | AC38: {=_xlfn.TEXTJOIN("-",TRUE,IF(TRIM(U38:AA38)="","",TRIM(U38:AA38)))} -> Front | AD38: {=_xlfn.TEXTJOIN("",TRUE,LEFT(U38:AA38,1))} -> F | AE38: {=_xlfn.TEXTJOIN("/",TRUE,LEFT(U38:AA38,1))&"/"} -> F/ | AF38: {=_xlfn.TEXTJOIN("-",TRUE,LEFT(U38:AA38,1))&"-"} -> F-
A39: PT38 | B39: Baby Bodysuit | C39: PT38 | T39: F38 | U39: Front | AB39: {=_xlfn.TEXTJOIN(" ",TRUE,IF(TRIM(U39:AA39)="","",TRIM(U39:AA39)))} -> Front | AC39: {=_xlfn.TEXTJOIN("-",TRUE,IF(TRIM(U39:AA39)="","",TRIM(U39:AA39)))} -> Front | AD39: {=_xlfn.TEXTJOIN("",TRUE,LEFT(U39:AA39,1))} -> F | AE39: {=_xlfn.TEXTJOIN("/",TRUE,LEFT(U39:AA39,1))&"/"} -> F/ | AF39: {=_xlfn.TEXTJOIN("-",TRUE,LEFT(U39:AA39,1))&"-"} -> F-
A40: PT39 | B40: Baby Bib | C40: PT39 | T40: F39 | U40: Front | AB40: {=_xlfn.TEXTJOIN(" ",TRUE,IF(TRIM(U40:AA40)="","",TRIM(U40:AA40)))} -> Front | AC40: {=_xlfn.TEXTJOIN("-",TRUE,IF(TRIM(U40:AA40)="","",TRIM(U40:AA40)))} -> Front | AD40: {=_xlfn.TEXTJOIN("",TRUE,LEFT(U40:AA40,1))} -> F | AE40: {=_xlfn.TEXTJOIN("/",TRUE,LEFT(U40:AA40,1))&"/"} -> F/ | AF40: {=_xlfn.TEXTJOIN("-",TRUE,LEFT(U40:AA40,1))&"-"} -> F-
...

Sheet Guide1
A1: Supplier | B1: Brand | C1: Combined-Brand | D1: Department | E1: Sub-Department | F1: Brand-Code | G1: Product Name | H1: Daatadirect-Code | I1: china-code | J1: prodcuts Category | L1: prodcuts Category2 | M1: prodcuts Category3 | N1: prodcuts Category4 | O1: Amazon UK | P1: eBay UK | Q1: Etsy | R1: TikTok Shop UK | S1: Pinterest Shopping Categories | T1: Wix Stores | U1: Wix | V1: Category | W1: Google_Shopping | X1: Instagram | Y1: Pinterest | Z1: UNIVERSAL CATEGORY | AG1: Category | AO1: Tags
A3: BTC Activewear | B3: DaataaDirect | C3: Fruit Of The Loom/Gildan | D3: T-Shirts | E3: Unisex T-shirt | F3: 5000B | G3: TSHIRT | H3: DAT001 | I3: CH001 | J3: Apparel & Fashion | K3: Dropshipping | L3: Apparel | M3: T-Shirts | N3: Apparel & Accessories > Clothing > Shirts & Tops | O3: Books | P3: Antiques | Q3: Accessories | R3: Apparel & Accessories | S3: Home Decor | T3: Fashion | U3: Fashion | V3: Clothing & Accessories | W3: Apparel & Accessories | X3: Apparel & Accessories | Y3: Home Decor | Z3: Fashion & Apparel | AA3: Ready Made | AB3: Newborn | AC3: S1 | AD3: Newborn | AE3: INF-NB | AF3: 0-3 months | AO3: print on demand, personalised, custom, gift, apparel, t-shirts, #printondemand, #customgift, #customclothing
A4: Ralawise | B4: Giftvolt | C4: Daataa Direct | D4: T-Shirts | E4: Premium T-shirt | F4: 5000L | G4: TSHIRT | H4: DAT002 | I4: CH002 | J4: Beauty & Cosmetics | K4: Print-on-Demand | L4: Other | M4: Baby & Kids Apparel | N4: Apparel & Accessories > Clothing | O4: Business, Industry & Science | P4: Art | Q4: Art & Collectibles | R4: Beauty & Personal Care | S4: Fashion (Women / Men) | T4: Beauty & Wellness | U4: Beauty & Wellness | V4: Jewelry | W4: Media | X4: Beauty | Y4: Fashion | Z4: T-shirts | AA4: Your Photo/Image | AB4: 3 Months | AC4: S2 | AD4: 3 Months | AE4: INF-3M | AF4: 3-6 months | AO4: print on demand, personalised, custom, gift, apparel, t-shirts, #printondemand, #customgift, #customclothing
A5: Pencarrie | B5: Printvolt | C5: Gofasiondirect | D5: T-Shirts | E5: Heavy Cotton T-shirt | F5: 5100P | G5: BBWEAR | H5: DAT003 | I5: CH003 | J5: Electronics & Gadgets | K5: Print-on-Demand/Apparel & Fashion | L5: Drinkware | M5: Unclassified | N5: Apparel & Accessories | O5: Car & Motorbike | P5: Baby | Q5: Bags & Purses | R5: Home & Living | S5: Beauty | T5: Home & Decor | U5: Home & Decor | V5: Beauty & Personal Care | W5: Home & Garden | X5: Home | Y5: Beauty | Z5: Hoodies | AA5: Your Text | AB5: 6 Months | AC5: S3 | AD5: 6 Months | AE5: INF-6M | AF5: 6-9 months | AG5: Apparel & Fashion | AO5: print on demand, personalised, custom, gift, apparel, t-shirts, #printondemand, #customgift, #customclothing
A6: Uneek Clothing | B6: Foodvolt | C6: Printvolt | D6: T-Shirts | E6: Oversized T-shirt | F6: 64000 | G6: TSHIRT | H6: DAT004 | I6: CH004 | J6: Jewelry & Accessories | L6: Home & Living | M6: Hoodies & Sweatshirts | N6: Apparel & Accessories > Clothing > Pants | O6: Clothing | P6: Books, Comics & Magazines | Q6: Bath & Beauty | R6: Kitchenware | S6: DIY & Crafts | T6: Electronics | U6: Electronics | V6: Home & Garden | W6: Beauty | X6: Electronics | Y6: DIY & Crafts | Z6: Sweatshirts | AA6: Your Photo/Image & Your Text | AB6: 9 Months | AC6: S4 | AD6: 9 Months | AE6: INF-9M | AF6: 9-12 months | AG6: Beauty & Cosmetics | AO6: print on demand, personalised, custom, gift, apparel, t-shirts, #printondemand, #customgift, #customclothing
A7: Absolute Apparel | B7: B&C Collection | D7: T-Shirts | E7: Women’s Fitted T-shirt | F7: 64000B | G7: TSHIRT | H7: DAT005 | I7: CH005 | J7: Home & Kitchen Products | L7: Accessories | M7: Tanks & Vests | N7: Apparel & Accessories > Clothing > Activewear | O7: Computers & Accessories | P7: Business, Office & Industrial | Q7: Books, Films & Music | R7: Electronics | S7: Gifts | T7: Art | U7: Art | V7: Electronics | W7: Health | X7: Art | Y7: Gifts | Z7: Joggers | AA7: Your Photo/Image with Design Text | AB7: 12 Months | AC7: S5 | AD7: 12 Months | AE7: INF-12M | AF7: 12-18 months | AG7: Electronics & Gadgets | AO7: print on demand, personalised, custom, gift, apparel, t-shirts, #printondemand, #customgift, #customclothing
A8: MDP Supplies | B8: Babybugz | D8: T-Shirts | E8: Long Sleeve T-shirt | F8: 64000CVC | G8: TSHIRT | H8: DAT006 | I8: CH006 | J8: Digital Products (eBooks, Courses) | L8: Stationery | M8: Polos | N8: Apparel & Accessories > Clothing > Sleepwear & Loungewear | O8: DIY & Tools | P8: Cameras & Photography | Q8: Clothing | R8: Collectibles | S8: Art / Wall Art | T8: Jewellery | U8: Jewellery | V8: Art | W8: Toys & Games | X8: Jewelry | Y8: Art | Z8: Dresses | AA8: Your Text with Design Image | AB8: 18 Months | AC8: S6 | AD8: 18 Months | AE8: INF-18M | AF8: 18-24 months | AG8: Jewelry & Accessories | AO8: print on demand, personalised, custom, gift, apparel, t-shirts, #printondemand, #customgift, #customclothing
A9: Temu | B9: Bagbase | D9: T-Shirts | E9: V-neck T-shirt | F9: 64000L | G9: TSHIRT | H9: DAT007 | I9: CH007 | J9: Food & Beverages | L9: Digital Products | M9: Sports Jerseys | N9: Home & Garden > Kitchen & Dining > Drinkware > Mugs | O9: Electronics & Photo | P9: Cars, Motorcycles & Vehicles | Q9: Craft Supplies & Tools | R9: Toys & Hobbies | S9: Weddings | T9: Toys & Kids | U9: Toys & Kids | V9: Toys & Games | W9: Sporting Goods | X9: Sporting Goods | Y9: Weddings | Z9: Jackets | AA9: Your Text & Photo with Design | AB9: 2-3 Years | AC9: S7 | AD9: 2-3 Years | AE9: KID-2T | AF9: Toddler | AG9: Home & Kitchen Products | AO9: print on demand, personalised, custom, gift, apparel, t-shirts, #printondemand, #customgift, #customclothing
A10: Amazon | B10: Beechfield | D10: T-Shirts | E10: Ringer T-shirt | F10: 64001LCVC | G10: TSHIRT | H10: DAT008 | I10: CH008 | J10: Subscription Boxes | L10: Wall Art | M10: Leggings | N10: Home & Garden > Kitchen & Dining > Drinkware > Tumblers | O10: Garden & Outdoors | P10: Clothes, Shoes & Accessories | Q10: Electronics & Accessories | R10: Pet Supplies | S10: Party Ideas | T10: Pets | U10: Pets | V10: Baby & Kids | W10: Electronics | X10: Toys | Y10: Party Ideas | Z10: Co-ords | AA10: standard | AB10: 3-4 Years | AC10: S8 | AD10: 3-4 Years | AE10: KID-3T | AF10: Toddler | AG10: Digital Products (eBooks, Courses) | AO10: print on demand, personalised, custom, gift, apparel, t-shirts, #printondemand, #customgift, #customclothing
A11: eBay | B11: Bella+Canvas | D11: T-Shirts | E11: Pocket T-shirt | F11: 64200 | G11: TSHIRT | H11: DAT009 | I11: CH009 | L11: Photo Gifts | M11: Pants & Joggers | N11: Home & Garden > Kitchen & Dining > Drinkware > Water Bottles | O11: Grocery | P11: Collectables | Q11: Home & Living | R11: Food & Beverage | S11: Kids & Baby | T11: Digital Products | U11: Digital Products | V11: Sports | W11: Office Supplies | X11: Pet Supplies | Y11: Kids & Baby | Z11: Socks & Underwear | AA11: Photo Only | AB11: 4-5 Years | AC11: S9 | AD11: 4-5 Years | AE11: KID-4T | AF11: Toddler | AG11: Food & Beverages | AO11: print on demand, personalised, custom, gift, apparel, t-shirts, #printondemand, #customgift, #customclothing
A12: Alibaba | B12: Clique (NEW EXCLUSIVE) | D12: T-Shirts | E12: Kids T-shirt | F12: 64200L | G12: TSHIRT | H12: DAT010 | I12: CH010 | L12: Packaging & Branding | M12: Shorts | N12: Home & Garden > Kitchen & Dining > Drinkware > Drinking Glasses | O12: Health & Personal Care | P12: Computers, Tablets & Network Hardware | Q12: Jewellery | R12: Health | S12: Food & Recipes | T12: Gifts | U12: Gifts | V12: Food & Drink | W12: Pet Supplies | X12: Bags | Y12: Food & Recipes | Z12: Shoes | AA12: Name Only | AB12: 5-6 Years | AC12: S10 | AD12: 5-6 Years | AE12: KID-5T | AF12: Toddler | AG12: Subscription Boxes | AO12: print on demand, personalised, custom, gift, apparel, t-shirts, #printondemand, #customgift, #customclothing
A13: AliExpress | B13: Craft Sportswear (EXCLUSIVE) | D13: Baby & Kids Apparel | E13: Baby Bodysuit | F13: 64400 | G13: TSHIRT | H13: DAT011 | I13: CH011 | L13: Seasonal Gifts | M13: Sleepwear | N13: Home & Garden > Linens & Bedding > Decorative Pillows | O13: Home & Kitchen | P13: Crafts | Q13: Paper & Party Supplies | S13: Holidays & Events | T13: Food & Drink | U13: Food & Drink | V13: Gifts | W13: Luggage & Bags | X13: Shoes | Y13: Holidays | Z13: Bags | AA13: text Only | AB13: 6-7 Years | AC13: S11 | AD13: 6-7 Years | AE13: KID-6 | AF13: Kids | AG13: Dropshipping | AO13: print on demand, personalised, custom, gift, apparel, baby & kids apparel, #printondemand, #customgift, #customclothing
A14: Etsy | B14: Craghoppers Expert | D14: Unclassified | E14: Baby Bib | F14: 64800 | G14: PSHIRT | H14: DAT012 | I14: CH012 | L14: Pet Products | M14: Mugs | N14: Home & Garden > Linens & Bedding > Blankets | O14: Jewellery & Watches | P14: Dolls & Bears | Q14: Pet Supplies | S14: Pets | T14: DIY & Crafts | U14: DIY & Crafts | V14: Pet Supplies | W14: Baby & Toddler | X14: Furniture | Y14: Pets | Z14: B. Jewelry & Accessories | AA14: Photo + Text | AB14: 7-8 Years | AC14: S12 | AD14: 7-8 Years | AE14: KID-7 | AF14: Kids | AG14: Print-on-Demand | AO14: print on demand, personalised, custom, gift, other, unclassified, #printondemand, #customgift
A15: 1688 | B15: Delta Plus | D15: Hoodies & Sweatshirts | E15: Unisex Hoodie | F15: 64800L | G15: PSHIRT | H15: DAT013 | I15: CH013 | L15: Jewellery | M15: Tumblers | N15: Home & Garden > Linens & Bedding > Towels | O15: Pet Supplies | P15: Garden & Patio | Q15: Shoes | S15: Technology | T15: Socks & Underwear | W15: Vehicles & Parts | X15: Collectibles | Y15: Technology | Z15: Necklaces | AA15: Template with custom Date | AB15: 8-9 Years | AC15: S13 | AD15: 8-9 Years | AE15: KID-8 | AF15: Kids | AO15: print on demand, personalised, custom, gift, apparel, hoodies & sweatshirts, #printondemand, #customgift, #customclothing
A16: B&Q | B16: Dennys | D16: Hoodies & Sweatshirts | E16: Pullover Hoodie | F16: 64V00 | G16: TSHIRT | H16: DAT014 | I16: CH014 | M16: Bottles & Flasks | N16: Home & Garden > Kitchen & Dining > Kitchen Linens | O16: Sports & Outdoors | P16: Health & Beauty | Q16: Toys & Games | S16: Garden & Outdoor | T16: Shoes | W16: Arts & Entertainment | X16: Gifts | Y16: Garden & Outdoor | Z16: Bracelets | AA16: Template with custom Name | AB16: 9-10 Years | AC16: S14 | AD16: 9-10 Years | AE16: KID-9 | AF16: Kids | AO16: print on demand, personalised, custom, gift, apparel, hoodies & sweatshirts, #printondemand, #customgift, #customclothing
A17: Wickes | B17: Derby of Sweden (EXCLUSIVE) | D17: Hoodies & Sweatshirts | E17: Zip Hoodie | F17: 64V00L | G17: TSHIRT | H17: DAT015 | I17: CH015 | M17: Glassware & Barware | N17: Home & Garden > Rugs | O17: Toys & Games | P17: Home, Furniture & DIY | Q17: Weddings | S17: Travel | T17: Bags | W17: Hardware | Y17: Travel | Z17: Rings | AA17: Template with custom Text | AB17: 10-12 Years | AC17: S15 | AD17: 10-12 Years | AE17: KID-10 | AF17: Pre-Teen | AO17: print on demand, personalised, custom, gift, apparel, hoodies & sweatshirts, #printondemand, #customgift, #customclothing
A18: Screwfix | B18: ECOTote (EXCLUSIVE) | D18: Hoodies & Sweatshirts | E18: Crewneck Sweatshirt | F18: 65000 | G18: TSHIRT | H18: DAT016 | I18: CH016 | M18: Cushions & Pillows | N18: Luggage & Bags | O18: Video Games | P18: Jewellery & Watches | S18: Photography | W18: Furniture | Y18: Photography | Z18: Earrings | AA18: Template with custom photo | AB18: Extra Small | AC18: S16 | AD18: Extra Small | AE18: WM-XS | AF18: Size 6 (UK) / 2 (US) | AO18: print on demand, personalised, custom, gift, apparel, hoodies & sweatshirts, #printondemand, #customgift, #customclothing
A19: Toolstation | B19: Flexfit | D19: Hoodies & Sweatshirts | E19: Oversized Hoodie | F19: 65000B | G19: TSHIRT | H19: DAT017 | I19: CH017 | M19: Blankets & Bedding | N19: Electronics > Electronics Accessories > Bags, Cases & Sleeves | P19: Mobile Phones & Communication | Z19: Watches | AB19: Small | AC19: S17 | AD19: Small | AE19: WM-S | AF19: Size 8 (UK) / 4 (US) | AO19: print on demand, personalised, custom, gift, apparel, hoodies & sweatshirts, #printondemand, #customgift, #customclothing
A20: Amari Plastics | B20: Fruit of the Loom | D20: Hoodies & Sweatshirts | E20: Kids Hoodie | F20: 65000L | G20: TSHIRT | H20: DAT018 | I20: CH018 | M20: Towels | N20: Apparel & Accessories > Jewelry > Charms & Pendants | P20: Music | Z20: Hair Accessories | AB20: Medium | AC20: S18 | AD20: Medium | AE20: WM-M | AF20: Size 10 (UK) / 6 (US) | AO20: print on demand, personalised, custom, gift, apparel, hoodies & sweatshirts, #printondemand, #customgift, #customclothing
A21: China Suppliers | B21: Gildan | D21: Tanks & Vests | E21: Unisex Tank Top | F21: 8000 | G21: TSHIRT | H21: DAT019 | I21: CH019 | M21: Kitchen Textiles | N21: Apparel & Accessories > Handbags, Wallets & Cases | P21: Musical Instruments & DJ Equipment | Z21: Scarves & Gloves | AB21: Large | AC21: S19 | AD21: Large | AE21: WM-L | AF21: Size 12 (UK) / 8 (US) | AO21: print on demand, personalised, custom, gift, apparel, tanks & vests, #printondemand, #customgift, #customclothing
A22: Tilgear | B22: Gildan Hammer | D22: Tanks & Vests | E22: Women’s Racerback Tank | F22: 85800 | G22: PSHIRT | H22: DAT020 | I22: CH020 | M22: Rugs & Mats | N22: Office Supplies > General Office Supplies > Notebooks | P22: Pet Supplies | Z22: C. Beauty & Personal Care | AB22: X-Large | AC22: S20 | AD22: X-Large | AE22: WM-XL | AF22: Size 14 (UK) / 10 (US) | AO22: print on demand, personalised, custom, gift, apparel, tanks & vests, #printondemand, #customgift, #customclothing
A23: Indian | B23: Helly Hansen | D23: Polos | E23: Polo Shirt | F23: 85800L | G23: PSHIRT | H23: DAT021 | I23: CH021 | M23: Tote & Shopping Bags | N23: Office Supplies > General Office Supplies > Labels & Stickers | P23: Pottery, Porcelain & Glass | Z23: Skincare | AB23: 2X-Large | AC23: S21 | AD23: 2X-Large | AE23: WM-2XL | AF23: Size 16 (UK) / 12 (US) | AO23: print on demand, personalised, custom, gift, apparel, polos, #printondemand, #customgift, #customclothing
A24: Pakistan | B24: James Harvest (EXCLUSIVE) | D24: Sports Jerseys | E24: Sports Jersey | F24: 8800 | G24: PSHIRT | H24: DAT022 | I24: CH022 | M24: General Accessories | N24: Office Supplies > General Office Supplies > Calendars | P24: Sound & Vision | Z24: Bath & Body | AB24: 3X-Large | AC24: S22 | AD24: 3X-Large | AE24: WM-3XL | AF24: Size 18 (UK) / 14 (US) | AO24: print on demand, personalised, custom, gift, apparel, sports jerseys, #printondemand, #customgift, #customclothing
A25: Ikea | B25: James Harvest Outdoor (EXCLUSIVE) | D25: Leggings | E25: Leggings | F25: 8800B | G25: PSHIRT | H25: DAT023 | I25: CH023 | M25: Backpacks | N25: Office Supplies | P25: Sporting Goods | Z25: Haircare | AB25: Extra Small | AC25: S23 | AD25: Extra Small | AE25: MN-XS | AF25: 30-32 | AO25: print on demand, personalised, custom, gift, apparel, leggings, #printondemand, #customgift, #customclothing
A26: China + Amari Plastics | B26: Jerzees | D26: Pants & Joggers | E26: Joggers | F26: 980 | G26: TSHIRT | H26: DAT024 | I26: CH024 | M26: Travel & Gym Bags | N26: Software > Digital Goods & Currency | P26: Stamps | Z26: Perfume | AB26: Small | AC26: S24 | AD26: Small | AE26: MN-S | AF26: 34-36 | AO26: print on demand, personalised, custom, gift, apparel, pants & joggers, #printondemand, #customgift, #customclothing
B27: Jobman Workwear (EXCLUSIVE) | D27: Pants & Joggers | E27: Sweatpants | F27: SF000 | G27: SSHIRT | H27: DAT025 | I27: CH025 | M27: Keychains | N27: Home & Garden > Decor > Artwork > Posters, Prints, & Visual Artwork | P27: Toys & Games | Z27: Makeup | AB27: Medium | AC27: S25 | AD27: Medium | AE27: MN-M | AF27: 38-40 | AO27: print on demand, personalised, custom, gift, apparel, pants & joggers, #printondemand, #customgift, #customclothing
B28: Kustom Kit | D28: Shorts | E28: Shorts | F28: SF008 | G28: SSHIRT | H28: DAT026 | I28: CH026 | M28: Luggage Accessories | N28: Home & Garden > Decor | P28: Video Games & Consoles | Z28: D. Home & Living | AB28: Large | AC28: S26 | AD28: Large | AE28: MN-L | AF28: 42-44 | AO28: print on demand, personalised, custom, gift, apparel, shorts, #printondemand, #customgift, #customclothing
B29: Madeira | D29: Sleepwear | E29: Pyjama Set | F29: SF100 | G29: TROUSR | H29: DAT027 | I29: CH027 | M29: Wallets & Card Holders | N29: Home & Garden > Decor > Picture Frames | Z29: Wall Art | AB29: X-Large | AC29: S27 | AD29: X-Large | AE29: MN-XL | AF29: 46-48 | AO29: print on demand, personalised, custom, gift, apparel, sleepwear, #printondemand, #customgift, #customclothing
B30: Magic Touch | D30: Mugs | E30: 11oz Ceramic Mug | F30: SF500 | G30: SSHIRT | H30: DAT028 | I30: CH028 | M30: Notebooks & Journals | N30: Home & Garden > Kitchen & Dining > Drinkware | Z30: Posters | AB30: 2X-Large | AC30: S28 | AD30: 2X-Large | AE30: MN-2XL | AF30: 50-52 | AO30: print on demand, personalised, custom, gift, drinkware, mugs, #printondemand, #customgift, #custommug
B31: Mantis | D31: Mugs | E31: 15oz Ceramic Mug | F31: SF500B | G31: SSHIRT | H31: DAT029 | I31: CH029 | M31: Stickers & Labels | N31: Home & Garden > Window Treatments > Curtains & Drapes | Z31: Cushions | AB31: 3X-Large | AC31: S29 | AD31: 3X-Large | AE31: MN-3XL | AF31: 54-56 | AO31: print on demand, personalised, custom, gift, drinkware, mugs, #printondemand, #customgift, #custommug
B32: Nike | D32: Mugs | E32: Two-Tone Mug | F32: SF600 | G32: SSHIRT | H32: DAT030 | I32: CH030 | M32: Calendars | N32: Business & Industrial > Advertising & Marketing > Business Cards | Z32: Bedding | AB32: 4XL | AC32: S30 | AD32: 4XL | AE32: MN-4XL | AF32: 58-60 | AO32: print on demand, personalised, custom, gift, drinkware, mugs, #printondemand, #customgift, #custommug
B33: Printer Essentials (EXCLUSIVE) | D33: Mugs | E33: Magic Heat-Changing Mug | F33: H000 | G33: TSHIRT | H33: DAT031 | I33: CH031 | M33: Stationery | N33: Business & Industrial > Packing & Shipping Supplies | Z33: Kitchen Items | AB33: 5XL | AC33: S31 | AD33: 5XL | AE33: MN-5XL | AF33: 62-64 | AO33: print on demand, personalised, custom, gift, drinkware, mugs, #printondemand, #customgift, #custommug
B34: Printer Prime (EXCLUSIVE) | D34: Mugs | E34: Enamel Camp Mug | F34: H400 | G34: TSHIRT | H34: DAT032 | I34: CH032 | M34: Templates / Printables | N34: Home & Garden > Decor > Artwork | Z34: Candles | AB34: 6XL | AC34: S32 | AD34: 6XL | AE34: MN-6XL | AF34: 66-68 | AO34: print on demand, personalised, custom, gift, drinkware, mugs, #printondemand, #customgift, #custommug
B35: Printer Red (EXCLUSIVE) | D35: Mugs | E35: Travel Mug | F35: HF000 | G35: SSHIRT | H35: DAT033 | I35: CH033 | M35: Posters | N35: Home & Garden > Decor > Seasonal & Holiday Decorations | Z35: Decor | AB35: 7XL | AC35: S33 | AD35: 7XL | AE35: MN-7XL | AF35: 70-72 | AO35: print on demand, personalised, custom, gift, drinkware, mugs, #printondemand, #customgift, #custommug
B36: Puma Safety | D36: T-Shirts | E36: Stainless Steel Tumbler | F36: SS800 | G36: OUTERW | H36: DAT034 | I36: CH034 | M36: Art Prints | N36: Animals & Pet Supplies > Pet Supplies | Z36: Furniture | AB36: 8XL | AC36: S34 | AD36: 8XL | AE36: MN8XL | AF36: 74-76 | AO36: print on demand, personalised, custom, gift, apparel, t-shirts, #printondemand, #customgift, #customclothing
B37: Pure Earth by Stormtech | D37: Tumblers | E37: Insulated Tumbler | F37: SS800L | G37: OUTERW | H37: DAT035 | I37: CH035 | M37: Photo Personalised Gifts | N37: Apparel & Accessories > Clothing > Dresses | Z37: E. Art & Collectibles | AB37: A2 | AC37: S35 | AD37: A2 | AE37: 420.5*594mm | AO37: print on demand, personalised, custom, gift, drinkware, tumblers, #printondemand, #customgift, #custommug
B38: Quadra | D38: Bottles & Flasks | E38: Water Bottle Metal | F38: 70180 | G38: WKWEAR | H38: DAT036 | I38: CH036 | M38: Drinkware | N38: Apparel & Accessories > Clothing > Skirts | Z38: Prints | AB38: A2-1 | AC38: S36 | AD38: A2-1 | AE38: 140.166*594mm | AO38: print on demand, personalised, custom, gift, drinkware, bottles & flasks, #printondemand, #customgift, #custommug
B39: Regatta Professional | D39: Mugs | E39: Latte Mug | F39: 70480 | G39: WKWEAR | H39: DAT037 | I39: CH037 | M39: Table Linens | N39: Apparel & Accessories > Jewelry | Z39: Digital Art | AB39: A2-2 | AC39: S37 | AD39: A2-2 | AE39: 420.5*420.5mm | AO39: print on demand, personalised, custom, gift, drinkware, mugs, #printondemand, #customgift, #custommug
B40: Regatta High Visibility | D40: Glassware & Barware | E40: Beer Glass | F40: 71043 | G40: WKWEAR | H40: DAT038 | I40: CH038 | M40: Curtains & Drapes | N40: Home & Garden > Kitchen & Dining > Drinkware > Drinking Glasses | Z40: Paintings | AB40: A2-3 | AC40: S38 | AD40: A2-3 | AE40: 420.5*210.25mm | AO40: print on demand, personalised, custom, gift, drinkware, glassware & barware, #printondemand, #customgift, #custommug
B41: Regatta Honestly Made | D41: Glassware & Barware | E41: Wine Glass | F41: 71080 | G41: OUTERW | H41: DAT039 | I41: CH039 | M41: Home Textiles | N41: Home & Garden > Kitchen & Dining > Drinkware > Drinking Glasses | Z41: Photography | AB41: A2-4 | AC41: S39 | AD41: A2-4 | AE41: 420.5*148.5mm | AO41: print on demand, personalised, custom, gift, drinkware, glassware & barware, #printondemand, #customgift, #custommug
...

Sheet Guide2
A1: Sr | B1: Title | C1: Note | J1: Used By Base62 | K1: 0 | M1: A | O1: =M1&$K1 -> A0 | Q1: AA | S1: =K1&Q1 -> 0AA | U1: AB | X1: MC | Y1: Machine | AB1: A0 | AD1: =K$1&M$12&M1 -> 0LA | AF1: =M$16&M1 -> PA | AH1: =M$19&M$5&M1 -> SEA | AP1: Used By Base62 | AQ1: 0 | AS1: A | AU1: =AS1&$K1 -> A0 | AW1: AA | AY1: =AQ1&AW1 -> 0AA | BA1: AB | BD1: MC | BE1: Machine | BH1: A0 | BJ1: =AQ$1&AS$12&AS1 -> 0LA | BL1: =AS$16&AS1 -> PA | BN1: =AS$19&AS$5&AS1 -> SEA
A2: 1 | B2: A To Z | C2: BASE SKU | J2: Used By Base62 And Linking SKU Code | K2: 1 | M2: B | O2: =M2&$K2 -> B1 | Q2: BA | S2: =K2&Q2 -> 1BA | U2: BB | X2: MC | AB2: B1 | AD2: =K$1&M$12&M2 -> 0LB | AF2: =M$16&M2 -> PB | AH2: =M$19&M$5&M2 -> SEB | AP2: Used By Base62 And Linking SKU Code | AQ2: 1 | AS2: B | AU2: =AS2&$K2 -> B1 | AW2: BA | AY2: =AQ2&AW2 -> 1BA | BA2: BB | BD2: MC | BH2: B1 | BJ2: =AQ$1&AS$12&AS2 -> 0LB | BL2: =AS$16&AS2 -> PB | BN2: =AS$19&AS$5&AS2 -> SEB
A3: 2 | B3: 1 to unlimited | C3: btcactivewear | J3: Used By Linking SKU Code | K3: 2 | M3: C | O3: =M3&$K3 -> C2 | Q3: CA | S3: =K3&Q3 -> 2CA | U3: CB | X3: CT | AB3: C2 | AD3: =K$1&M$12&M3 -> 0LC | AF3: =M$16&M3 -> PC | AH3: =M$19&M$5&M3 -> SEC | AP3: Used By Linking SKU Code | AQ3: 2 | AS3: C | AU3: =AS3&$K3 -> C2 | AW3: CA | AY3: =AQ3&AW3 -> 2CA | BA3: CB | BD3: CT | BH3: C2 | BJ3: =AQ$1&AS$12&AS3 -> 0LC | BL3: =AS$16&AS3 -> PC | BN3: =AS$19&AS$5&AS3 -> SEC
A4: 3 | B4: 1-A | C4: ralawise | J4: Used For Designs | K4: 3 | M4: D | O4: =M4&$K4 -> D3 | Q4: DA | S4: =K4&Q4 -> 3DA | U4: DB | X4: CL | AB4: D3 | AD4: =K$1&M$12&M4 -> 0LD | AF4: =M$16&M4 -> PD | AH4: =M$19&M$5&M4 -> SED | AP4: Used For Designs | AQ4: 3 | AS4: D | AU4: =AS4&$K4 -> D3 | AW4: DA | AY4: =AQ4&AW4 -> 3DA | BA4: DB | BD4: CL | BH4: D3 | BJ4: =AQ$1&AS$12&AS4 -> 0LD | BL4: =AS$16&AS4 -> PD | BN4: =AS$19&AS$5&AS4 -> SED
A5: 4 | C5: PenCarrie | J5: Used For SET Listing | K5: 4 | M5: E | O5: =M5&$K5 -> E4 | Q5: EA | S5: =K5&Q5 -> 4EA | U5: EB | X5: PT | AB5: E4 | AD5: =K$1&M$12&M5 -> 0LE | AF5: =M$16&M5 -> PE | AH5: =M$19&M$5&M5 -> SEE | AP5: Used For SET Listing | AQ5: 4 | AS5: E | AT5: EVENT | AU5: =AS5&$K5 -> E4 | AW5: EA | AY5: =AQ5&AW5 -> 4EA | BA5: EB | BD5: PT | BH5: E4 | BJ5: =AQ$1&AS$12&AS5 -> 0LE | BL5: =AS$16&AS5 -> PE | BN5: =AS$19&AS$5&AS5 -> SEE
A6: 5 | C6: uneekclothing | K6: 5 | M6: F | O6: =M6&$K6 -> F5 | Q6: FA | S6: =K6&Q6 -> 5FA | U6: FB | X6: PG | AB6: F5 | AD6: =K$1&M$12&M6 -> 0LF | AF6: =M$16&M6 -> PF | AH6: =M$19&M$5&M6 -> SEF | AQ6: 5 | AS6: F | AU6: =AS6&$K6 -> F5 | AW6: FA | AY6: =AQ6&AW6 -> 5FA | BA6: FB | BD6: PG | BH6: F5 | BJ6: =AQ$1&AS$12&AS6 -> 0LF | BL6: =AS$16&AS6 -> PF | BN6: =AS$19&AS$5&AS6 -> SEF
A7: 6 | C7: absoluteapparel | K7: 6 | M7: G | O7: =M7&$K7 -> G6 | Q7: GA | S7: =K7&Q7 -> 6GA | U7: GB | X7: PRT | AB7: G6 | AD7: =K$1&M$12&M7 -> 0LG | AF7: =M$16&M7 -> PG | AH7: =M$19&M$5&M7 -> SEG | AQ7: 6 | AS7: G | AU7: =AS7&$K7 -> G6 | AW7: GA | AY7: =AQ7&AW7 -> 6GA | BA7: GB | BD7: PRT | BH7: G6 | BJ7: =AQ$1&AS$12&AS7 -> 0LG | BL7: =AS$16&AS7 -> PG | BN7: =AS$19&AS$5&AS7 -> SEG
A8: 7 | B8: DS1001S | C8: mdpsupplies | E8: M5 | I8: NOTE | K8: 7 | M8: H | O8: =M8&$K8 -> H7 | Q8: HA | S8: =K8&Q8 -> 7HA | U8: HB | X8: CG | AB8: H7 | AD8: =K$1&M$12&M8 -> 0LH | AF8: =M$16&M8 -> PH | AH8: =M$19&M$5&M8 -> SEH | AQ8: 7 | AS8: H | AU8: =AS8&$K8 -> H7 | AW8: HA | AY8: =AQ8&AW8 -> 7HA | BA8: HB | BD8: CG | BH8: H7 | BJ8: =AQ$1&AS$12&AS8 -> 0LH | BL8: =AS$16&AS8 -> PH | BN8: =AS$19&AS$5&AS8 -> SEH
A9: 8 | E9: LG | I9: 46002 | J9: B64 BEFORE NO LOW CASE | K9: 8 | M9: I | O9: =M9&$K9 -> I8 | Q9: IA | S9: =K9&Q9 -> 8IA | U9: IB | X9: MCG | AB9: I8 | AD9: =K$1&M$12&M9 -> 0LI | AF9: =M$16&M9 -> PI | AH9: =M$19&M$5&M9 -> SEI | AQ9: 8 | AS9: I | AU9: =AS9&$K9 -> I8 | AW9: IA | AY9: =AQ9&AW9 -> 8IA | BA9: IB | BD9: MCG | BH9: I8 | BJ9: =AQ$1&AS$12&AS9 -> 0LI | BL9: =AS$16&AS9 -> PI | BN9: =AS$19&AS$5&AS9 -> SEI
A10: 9 | E10: BTC | J10: B32 AFTER | K10: 9 | M10: J | O10: =M10&$K10 -> J9 | Q10: JA | S10: =K10&Q10 -> 9JA | U10: JB | X10: SS | AB10: J9 | AD10: =K$1&M$12&M10 -> 0LJ | AF10: =M$16&M10 -> PJ | AH10: =M$19&M$5&M10 -> SEJ | AQ10: 9 | AS10: J | AU10: =AS10&$K10 -> J9 | AW10: JA | AY10: =AQ10&AW10 -> 9JA | BA10: JB | BD10: SS | BH10: J9 | BJ10: =AQ$1&AS$12&AS10 -> 0LJ | BL10: =AS$16&AS10 -> PJ | BN10: =AS$19&AS$5&AS10 -> SEJ
A11: 10 | E11: FIVE SHEETS | K11: 10 | M11: K | O11: =M11&$K11 -> K10 | Q11: KA | S11: =K11&Q11 -> 10KA | U11: KB | X11: PC | AB11: K10 | AD11: =K$1&M$12&M11 -> 0LK | AF11: =M$16&M11 -> PK | AH11: =M$19&M$5&M11 -> SEK | AQ11: 10 | AS11: K | AU11: =AS11&$K11 -> K10 | AW11: KA | AY11: =AQ11&AW11 -> 10KA | BA11: KB | BD11: PC | BH11: K10 | BJ11: =AQ$1&AS$12&AS11 -> 0LK | BL11: =AS$16&AS11 -> PK | BN11: =AS$19&AS$5&AS11 -> SEK
A12: 11 | I12: SKU | J12: A1 | K12: 11 | M12: L | O12: =M12&$K12 -> L11 | Q12: LA | S12: =K12&Q12 -> 11LA | U12: LB | X12: V | AB12: L11 | AD12: =K$1&M$12&M12 -> 0LL | AF12: =M$16&M12 -> PL | AH12: =M$19&M$5&M12 -> SEL | AQ12: 11 | AS12: L | AU12: =AS12&$K12 -> L11 | AW12: LA | AY12: =AQ12&AW12 -> 11LA | BA12: LB | BD12: V | BH12: L11 | BJ12: =AQ$1&AS$12&AS12 -> 0LL | BL12: =AS$16&AS12 -> PL | BN12: =AS$19&AS$5&AS12 -> SEL
A13: 12 | I13: TILE | J13: A1 | K13: 12 | M13: M | O13: =I3&$K13 -> 12 | Q13: MA | S13: =K13&Q13 -> 12MA | U13: MB | X13: W | AB13: M12 | AD13: =K$1&M$12&M13 -> 0LM | AF13: =M$16&M13 -> PM | AH13: =M$19&M$5&M13 -> SEM | AQ13: 12 | AS13: M | AU13: =AO3&$K13 -> 12 | AW13: MA | AY13: =AQ13&AW13 -> 12MA | BA13: MB | BD13: W | BH13: M12 | BJ13: =AQ$1&AS$12&AS13 -> 0LM | BL13: =AS$16&AS13 -> PM | BN13: =AS$19&AS$5&AS13 -> SEM
A14: 13 | I14: DES | K14: 13 | M14: N | O14: =M14&$K14 -> N13 | Q14: NA | S14: =K14&Q14 -> 13NA | U14: NB | AB14: N13 | AD14: =K$1&M$12&M14 -> 0LN | AF14: =M$16&M14 -> PN | AH14: =M$19&M$5&M14 -> SEN | AQ14: 13 | AS14: N | AU14: =AS14&$K14 -> N13 | AW14: NA | AY14: =AQ14&AW14 -> 13NA | BA14: NB | BH14: N13 | BJ14: =AQ$1&AS$12&AS14 -> 0LN | BL14: =AS$16&AS14 -> PN | BN14: =AS$19&AS$5&AS14 -> SEN
A15: 14 | E15: 100LG-M-T-BLK-D | I15: TAGS | K15: 14 | M15: O | O15: =M15&$K15 -> O14 | Q15: OA | S15: =K15&Q15 -> 14OA | U15: OB | AB15: O14 | AD15: =K$1&M$12&M15 -> 0LO | AF15: =M$16&M15 -> PO | AH15: =M$19&M$5&M15 -> SEO | AQ15: 14 | AS15: O | AU15: =AS15&$K15 -> O14 | AW15: OA | AY15: =AQ15&AW15 -> 14OA | BA15: OB | BH15: O14 | BJ15: =AQ$1&AS$12&AS15 -> 0LO | BL15: =AS$16&AS15 -> PO | BN15: =AS$19&AS$5&AS15 -> SEO
A16: 15 | I16: PIONTS | K16: 15 | M16: P | O16: =M16&$K16 -> P15 | Q16: PA | S16: =K16&Q16 -> 15PA | U16: PB | AB16: P15 | AD16: =K$1&M$12&M16 -> 0LP | AF16: =M$16&M16 -> PP | AH16: =M$19&M$5&M16 -> SEP | AQ16: 15 | AS16: P | AU16: =AS16&$K16 -> P15 | AW16: PA | AY16: =AQ16&AW16 -> 15PA | BA16: PB | BH16: P15 | BJ16: =AQ$1&AS$12&AS16 -> 0LP | BL16: =AS$16&AS16 -> PP | BN16: =AS$19&AS$5&AS16 -> SEP
A17: 16 | I17: MOCK | J17: M | K17: 16 | M17: Q | O17: =M17&$K17 -> Q16 | Q17: QA | S17: =K17&Q17 -> 16QA | U17: QB | AB17: Q16 | AD17: =K$1&M$12&M17 -> 0LQ | AF17: =M$16&M17 -> PQ | AH17: =M$19&M$5&M17 -> SEQ | AQ17: 16 | AS17: Q | AU17: =AS17&$K17 -> Q16 | AW17: QA | AY17: =AQ17&AW17 -> 16QA | BA17: QB | BH17: Q16 | BJ17: =AQ$1&AS$12&AS17 -> 0LQ | BL17: =AS$16&AS17 -> PQ | BN17: =AS$19&AS$5&AS17 -> SEQ
A18: 17 | I18: PASTING | J18: P | K18: 17 | M18: R | O18: =M18&$K18 -> R17 | Q18: RA | S18: =K18&Q18 -> 17RA | U18: RB | AB18: R17 | AD18: =K$1&M$12&M18 -> 0LR | AF18: =M$16&M18 -> PR | AH18: =M$19&M$5&M18 -> SER | AQ18: 17 | AS18: R | AU18: =AS18&$K18 -> R17 | AW18: RA | AY18: =AQ18&AW18 -> 17RA | BA18: RB | BH18: R17 | BJ18: =AQ$1&AS$12&AS18 -> 0LR | BL18: =AS$16&AS18 -> PR | BN18: =AS$19&AS$5&AS18 -> SER
A19: 18 | K19: 18 | M19: S | O19: =M19&$K19 -> S18 | Q19: SA | S19: =K19&Q19 -> 18SA | U19: SB | AB19: S18 | AD19: =K$1&M$12&M19 -> 0LS | AF19: =M$16&M19 -> PS | AH19: =M$19&M$5&M19 -> SES | AQ19: 18 | AS19: S | AU19: =AS19&$K19 -> S18 | AW19: SA | AY19: =AQ19&AW19 -> 18SA | BA19: SB | BH19: S18 | BJ19: =AQ$1&AS$12&AS19 -> 0LS | BL19: =AS$16&AS19 -> PS | BN19: =AS$19&AS$5&AS19 -> SES
A20: 19 | K20: 19 | M20: T | O20: =M20&$K20 -> T19 | Q20: TA | S20: =K20&Q20 -> 19TA | U20: TB | AB20: T19 | AD20: =K$1&M$12&M20 -> 0LT | AF20: =M$16&M20 -> PT | AH20: =M$19&M$5&M20 -> SET | AQ20: 19 | AS20: T | AU20: =AS20&$K20 -> T19 | AW20: TA | AY20: =AQ20&AW20 -> 19TA | BA20: TB | BH20: T19 | BJ20: =AQ$1&AS$12&AS20 -> 0LT | BL20: =AS$16&AS20 -> PT | BN20: =AS$19&AS$5&AS20 -> SET
A21: 20 | K21: 20 | M21: U | O21: =M21&$K21 -> U20 | Q21: UA | S21: =K21&Q21 -> 20UA | U21: UB | AB21: U20 | AD21: =K$1&M$12&M21 -> 0LU | AF21: =M$16&M21 -> PU | AH21: =M$19&M$5&M21 -> SEU | AQ21: 20 | AS21: U | AU21: =AS21&$K21 -> U20 | AW21: UA | AY21: =AQ21&AW21 -> 20UA | BA21: UB | BH21: U20 | BJ21: =AQ$1&AS$12&AS21 -> 0LU | BL21: =AS$16&AS21 -> PU | BN21: =AS$19&AS$5&AS21 -> SEU
A22: 21 | K22: 21 | M22: V | O22: =M22&$K22 -> V21 | Q22: VA | S22: =K22&Q22 -> 21VA | U22: VB | AB22: V21 | AD22: =K$1&M$12&M22 -> 0LV | AF22: =M$16&M22 -> PV | AH22: =M$19&M$5&M22 -> SEV | AQ22: 21 | AS22: V | AU22: =AS22&$K22 -> V21 | AW22: VA | AY22: =AQ22&AW22 -> 21VA | BA22: VB | BH22: V21 | BJ22: =AQ$1&AS$12&AS22 -> 0LV | BL22: =AS$16&AS22 -> PV | BN22: =AS$19&AS$5&AS22 -> SEV
A23: 22 | K23: 22 | M23: W | O23: =M23&$K23 -> W22 | Q23: WA | S23: =K23&Q23 -> 22WA | U23: WB | AB23: W22 | AD23: =K$1&M$12&M23 -> 0LW | AF23: =M$16&M23 -> PW | AH23: =M$19&M$5&M23 -> SEW | AQ23: 22 | AS23: W | AU23: =AS23&$K23 -> W22 | AW23: WA | AY23: =AQ23&AW23 -> 22WA | BA23: WB | BH23: W22 | BJ23: =AQ$1&AS$12&AS23 -> 0LW | BL23: =AS$16&AS23 -> PW | BN23: =AS$19&AS$5&AS23 -> SEW
A24: 23 | I24: M-T | K24: 23 | M24: X | O24: =M24&$K24 -> X23 | Q24: XA | S24: =K24&Q24 -> 23XA | U24: XB | AB24: X23 | AD24: =K$1&M$12&M24 -> 0LX | AF24: =M$16&M24 -> PX | AH24: =M$19&M$5&M24 -> SEX | AQ24: 23 | AS24: X | AU24: =AS24&$K24 -> X23 | AW24: XA | AY24: =AQ24&AW24 -> 23XA | BA24: XB | BH24: X23 | BJ24: =AQ$1&AS$12&AS24 -> 0LX | BL24: =AS$16&AS24 -> PX | BN24: =AS$19&AS$5&AS24 -> SEX
A25: 24 | K25: 24 | M25: Y | O25: =M25&$K25 -> Y24 | Q25: YA | S25: =K25&Q25 -> 24YA | U25: YB | AB25: Y24 | AD25: =K$1&M$12&M25 -> 0LY | AF25: =M$16&M25 -> PY | AH25: =M$19&M$5&M25 -> SEY | AQ25: 24 | AS25: Y | AU25: =AS25&$K25 -> Y24 | AW25: YA | AY25: =AQ25&AW25 -> 24YA | BA25: YB | BH25: Y24 | BJ25: =AQ$1&AS$12&AS25 -> 0LY | BL25: =AS$16&AS25 -> PY | BN25: =AS$19&AS$5&AS25 -> SEY
A26: 25 | D26: OLD 2013 90% | F26: 62480LG-K-H-DHR-YL | K26: 25 | M26: Z | O26: =M26&$K26 -> Z25 | Q26: ZA | S26: =K26&Q26 -> 25ZA | U26: ZB | AB26: Z25 | AD26: =K$1&M$12&M26 -> 0LZ | AF26: =M$16&M26 -> PZ | AH26: =M$19&M$5&M26 -> SEZ | AQ26: 25 | AS26: Z | AU26: =AS26&$K26 -> Z25 | AW26: ZA | AY26: =AQ26&AW26 -> 25ZA | BA26: ZB | BH26: Z25 | BJ26: =AQ$1&AS$12&AS26 -> 0LZ | BL26: =AS$16&AS26 -> PZ | BN26: =AS$19&AS$5&AS26 -> SEZ
D27: OLD 2013 90% | E27: OLD 2021 | F27: 6081LG-DM-F/S-F4-M-H-WHI-XL 37798LG-DM-S1-M-H-WHI-XL | G27: DM-F/S-F4 | H27: DM-S1 | I27: M-H-WHI-XL | J27: 6081LG/37798LG -DM-F/S-F4-DM-S1-M-H-WHI-XL
D28: OLD 2013 90% | E28: OLD 2021 | F28: Plain-BG-BG125-MUD-O/S | G28: Plain-BG | I28: BG125-MUD-O/S
D29: OLD 2013 90% | F29: 112637LG-BG-QD457-BGNDY-O/S-YES
D30: OLD 2013 90% | F30: 129010LG-C8030T-BS-WHI-0-3M-Yes | G30: DG-DM | H30: DG-F/S-F4-W-T-BLK-XL | I30: DM-F/S-F4-K-T-BLK-YL 32360LG-DM-S1-K-T-BLK-YL
D31: OLD 2013 90% | E31: OLD 2021 | F31: 6081LG-DM-F/S-F4-M-H-WHI-XL 37798LG-DM-S1-M-H-WHI-XL
D32: OLD 2013 90% | E32: OLD 2022 | F32: 48813LG-DTF-IronOn-A4-YES
E34: 2025
F35: 62480LG-K-H-DHR-YL
F36: 6081LG-DM-F/S-F4-M-H-WHI-XL 37798LG-DM-S1-M-H-WHI-XL
F37: Plain-BG-BG125-MUD-O/S
F38: 112637LG-BG-QD457-BGNDY-O/S-YES
F39: 129010LG-C8030T-BS-WHI-0-3M-Yes
F40: 6081LG-DM-F/S-F4-M-H-WHI-XL 37798LG-DM-S1-M-H-WHI-XL
F41: 48813LG-DTF-IronOn-A4-YES
...

Sheet Guide3
